Workbook

Sheet Assumptions
A2: ASSUMPTIONS: (For WACC) | B2: ASSSUMPTIONS: (Forecast)
A4: (1)Normalized tax rate = 20% | B4: (1) Revenue Growth: | C4: Terminal growth rate = 2.25%
A5: Rationale: Long-run blended effective tax rate for large US healthcare firms | B5: 2025E: 4.5% | C5: Rationale: Conservative long-run growth aligned with inflation and global GDP for a mature healthcare company.
B6: 2026E: 4.0% | C6: A terminal growth rate of 2.25% is used to reflect conservative long-run growth aligned with expected inflation and nominal global GDP growth.
A7: (2) Risk-free rate = 4.2% | B7: 2027E: 3.5% | C7: Given Johnson & Johnson’s mature business profile, diversified healthcare exposure, and stable end-market demand, this assumption avoids overstating perpetual growth while remaining economically sustainable
A8: US 10Y Treasury yield | B8: 2028E: 3.0%
B9: 2029E: 2.5%
A10: (3) Beta used = 0.35 | B10: Rationale:
A11: Rationale: Raw beta (5Y monthly) = 0.35 | B11: Based on historical 2021–2024 revenue CAGR of ~4%
A12: The beta used is the raw 5-year monthly beta of 0.35, which reflects Johnson & Johnson’s low systematic risk and defensive business profile | B12: Reflects J&J’s mature, diversified healthcare portfolio
A13: Given the company’s diversified healthcare operations, stable cash flows, and limited sensitivity to economic cycles | B13: Growth is gradually faded toward long-term healthcare and GDP growth
A14: The raw beta is considered a reasonable proxy for its current market risk perception | B14: Avoids extrapolating short-term acceleration
A16: (4) Implied long-run market return ≈ 10.0% | B16: (2) EBIT Margin (% of Sales):
A17: Rationale: | B17: 21.0% (flat across forecast period)
A18: Risk-free rate (US 10Y) = 4.2% | B18: Rationale:
A19: Equity Risk Premium (ERP) = 5.8% | B19: 2021–22 margins (~25%) were elevated and not representative
A20: Implied long-run market return ≈ 10.0% | B20: 2023–24 margins (~19–20%) reflect post-normalization levels
A21: (reference: historical S&P 500 average) | B21: 21% represents a sustainable mid-cycle operating margin
B22: Flat margin avoids aggressive margin expansion assumptions
B24: (3) Depreciation & Amortization (% of Sales)
B25: 8.7% of revenue
B26: Rationale:
B27: Historical D&A has been highly stable in the 8–9% range
B28: J&J’s asset base and depreciation policy are mature and predictable
B29: D&A is modeled as a normalized ratio to reflect steady capital intensity
B30: Avoids unnecessary asset-life assumptions that do not affect cash flow materially
B32: (4) Capital Expenditure (% of Sales)
B33: 2025E: 6.5%
B34: 2026E: 6.3%
B35: 2027E: 6.0%
... B50: Consistent with stable inventory and receivables management

Sheet Operating Forecast
A3: Johnson & Johnson (J&J)DCF
A5: Ticker | C5: JNJ | E5: Implied Price Per Share | G5: 189.6 | M5: ALL FIGURES ARE in MILLIONS (USD)
A6: Date | C6: 46017 | E6: Current Share Price | G6: 208.17
A7: Year end | C7: 46022 | E7: Implied Downside | G7: =((G6-G5)/G6) -> 0.089205937
B9: 2021A | C9: 2022A | D9: 2023A | E9: 2024A | F9: 2025E | G9: 2026E | H9: 2027E | I9: 2028E | J9: 2029E
A10: Revenue | B10: 78740 | C10: 79990 | D10: 85159 | E10: 88821 | F10: =E10*(1+F11) -> 92817.945 | G10: =F10*(1+G11) -> 96530.663 | H10: =G10*(1+H11) -> 99909.236 | I10: =H10*(1+I11) -> 102906.51 | J10: =I10*(1+J11) -> 105479.18
A11: % growth | B11: - | C11: =(C10-B10)/B10 -> 0.015875032 | D11: =(D10-C10)/C10 -> 0.064620578 | E11: =(E10-D10)/D10 -> 0.043001914 | F11: 0.045 | G11: 0.04 | H11: 0.035 | I11: 0.03 | J11: 0.025
A13: EBIT | B13: 19361 | C13: 19635 | D13: 15834 | E13: 17442 | F13: =F10*F15 -> 19491.768 | G13: =G10*G15 -> 20271.439 | H13: =H10*H15 -> 20980.94 | I13: =I10*I15 -> 21610.368 | J13: =J10*J15 -> 22150.627
A14: % growth | B14: - | C14: =(C13-B13)/B13 -> 0.014152162 | D14: =(D13-C13)/C13 -> -0.19358289 | E14: =(E13-D13)/D13 -> 0.10155362 | F14: =(F13-E13)/E13 -> 0.11751912 | G14: =(G13-F13)/F13 -> 0.04 | H14: =(H13-G13)/G13 -> 0.035 | I14: =(I13-H13)/H13 -> 0.03 | J14: =(J13-I13)/I13 -> 0.025
A15: % of sales | B15: =B13/B10 -> 0.24588519 | C15: =C13/C10 -> 0.24546818 | D15: =D13/D10 -> 0.18593455 | E15: =E13/E10 -> 0.19637248 | F15: 0.21 | G15: 0.21 | H15: 0.21 | I15: 0.21 | J15: 0.21
A17: D&A | B17: 7390 | C17: 6970 | D17: 7486 | E17: 7339 | F17: =F10*F18 -> 8075.1612 | G17: =G10*G18 -> 8398.1677 | H17: =H10*H18 -> 8692.1035 | I17: =I10*I18 -> 8952.8666 | J17: =J10*J18 -> 9176.6883
A18: % of sales | B18: =B17/B10 -> 0.093853188 | C18: =C17/C10 -> 0.087135892 | D18: =D17/D10 -> 0.087906152 | E18: =E17/E10 -> 0.082626856 | F18: 0.087 | G18: 0.087 | H18: 0.087 | I18: 0.087 | J18: 0.087
A20: CapEx | B20: 3652 | C20: 4009 | D20: 5013 | E20: 6207 | F20: =F10*F21 -> 6033.1664 | G20: =G10*G21 -> 6081.4318 | H20: =H10*H21 -> 5994.5542 | I20: =I10*I21 -> 5968.5778 | J20: =J10*J21 -> 5801.3547
A21: % of sales | B21: =B20/B10 -> 0.046380493 | C21: =C20/C10 -> 0.050118765 | D21: =D20/D10 -> 0.058866356 | E21: =E20/E10 -> 0.069882122 | F21: 0.065 | G21: 0.063 | H21: 0.06 | I21: 0.058 | J21: 0.055
A23: Change in NOWC | B23: -4238 | C23: -4011 | D23: 2507 | E23: 1837 | F23: =F10*F24 -> 928.17945 | G23: =G10*G24 -> 965.30663 | H23: =H10*H24 -> 999.09236 | I23: =I10*I24 -> 1029.0651 | J23: =J10*J24 -> 1054.7918
A24: % of sales | B24: =B23/B10 -> -0.053822708 | C24: =C23/C10 -> -0.050143768 | D24: =D23/D10 -> 0.029439049 | E24: =E23/E10 -> 0.020682046 | F24: 0.01 | G24: 0.01 | H24: 0.01 | I24: 0.01 | J24: 0.01

Sheet WACC
A2: WACC Calculation
A4: Equity value | B4: =Income_Statement_FULL!E18*'Operating Forecast'!G6 -> 505728.2
A5: Debt value | B5: =Balance_Sheet_FULL!F32+Balance_Sheet_FULL!F36 -> 36634
A6: Cost of Debt | B6: =((Cash_Flow_FULL!F8)/((Balance_Sheet_FULL!F36+Balance_Sheet_FULL!F32+Balance_Sheet_FULL!E32+Balance_Sheet_FULL!E36)/2)) -> 0.060334112
A7: Tax rate | B7: 0.2
A8: 10y Treasury (Rf) | B8: 0.042
A9: Beta | B9: 0.35
A10: Market Return | B10: 0.1
A11: Cost of Equity | B11: =B8+B9*(B10-B8) -> 0.0623
A13: E / D +E (We) | B13: =B4/(B4+B5) -> 0.93245473 | D13: ALL FIGURES ARE in MILLIONS (USD)
A14: D / D+E (Wd) | B14: =B5/(B4+B5) -> 0.067545268 | D14: ALL THE ASSUMPTIONS ARE LISTED IN FIRST SHEET WITH RATIONALE (Assumptions)
A15: WACC | B15: =(B13*B11+B14*B6*(1-B7)) -> 0.061352157

Sheet FCF
A2: Calculate the FCF | F2: ALL FIGURES ARE in MILLIONS (USD)
A4: FCF (2024)
A5: EBIT | B5: 17442
A6: Tax Rate % (Assumption) | B6: 0.2
A7: Depreciation and Amortization | B7: 7339
A8: CapEx | B8: 6207
A9: Change in NOWC | B9: 1837
A11: Free Cash Flow | B11: =B5*(1-B6)+B7-B8-B9 -> 13248.6

Sheet Terminal Value
A3: Terminal Value Calculation
A5: WACC | B5: 0.0614
A6: Growth rate | B6: 0.0225
A8: Period | B8: 0 | C8: 1 | D8: 2 | E8: 3 | F8: 4 | G8: 5
A9: FCF | C9: ='Operating Forecast'!F13*(1-20%)+'Operating Forecast'!F17-'Operating Forecast'!F20-'Operating Forecast'!F23 -> 16707.23 | D9: ='Operating Forecast'!G13*(1-20%)+'Operating Forecast'!G17-'Operating Forecast'!G20-'Operating Forecast'!G23 -> 17568.581 | E9: ='Operating Forecast'!H13*(1-20%)+'Operating Forecast'!H17-'Operating Forecast'!H20-'Operating Forecast'!H23 -> 18483.209 | F9: ='Operating Forecast'!I13*(1-20%)+'Operating Forecast'!I17-'Operating Forecast'!I20-'Operating Forecast'!I23 -> 19243.518 | G9: ='Operating Forecast'!J13*(1-20%)+'Operating Forecast'!J17-'Operating Forecast'!J20-'Operating Forecast'!J23 -> 20041.043
F11: Perpertuity Growth TV | G11: =((G9*(1+B6))/(B5-B6)) -> 526785.78
J12: ALL FIGURES ARE in MILLIONS (USD)

Sheet Discounting
A4: Discounting Cash Flows
A6: WACC | B6: 0.0614
A8: Period | B8: 0 | C8: 1 | D8: 2 | E8: 3 | F8: 4 | G8: 5
A9: FCF | C9: ='Operating Forecast'!F13*(1-20%)+'Operating Forecast'!F17-'Operating Forecast'!F20-'Operating Forecast'!F23 -> 16707.23 | D9: ='Operating Forecast'!G13*(1-20%)+'Operating Forecast'!G17-'Operating Forecast'!G20-'Operating Forecast'!G23 -> 17568.581 | E9: ='Operating Forecast'!H13*(1-20%)+'Operating Forecast'!H17-'Operating Forecast'!H20-'Operating Forecast'!H23 -> 18483.209 | F9: ='Operating Forecast'!I13*(1-20%)+'Operating Forecast'!I17-'Operating Forecast'!I20-'Operating Forecast'!I23 -> 19243.518 | G9: ='Operating Forecast'!J13*(1-20%)+'Operating Forecast'!J17-'Operating Forecast'!J20-'Operating Forecast'!J23 -> 20041.043
A10: Terminal Value | G10: 526785.8
A11: Discount factor | C11: =1/(1+$B6)^C8 -> 0.94215187 | D11: =1/(1+$B6)^D8 -> 0.88765016 | E11: =1/(1+$B6)^E8 -> 0.83630126 | F11: =1/(1+$B6)^F8 -> 0.7879228 | G11: =1/(1+$B6)^G8 -> 0.74234294
A13: PV of FCF | C13: =C9*C11 -> 15740.748 | D13: =D9*D11 -> 15594.753 | E13: =E9*E11 -> 15457.531 | F13: =F9*F11 -> 15162.407 | G13: =G9*G11 -> 14877.327
A14: PV of TV | G14: =G10*G11 -> 391055.72
A16: Enterprise Value | B16: =SUM(C13,D13,E13,F13,G13,G14) -> 467888.49
J17: ALL FIGURES ARE in MILLIONS (USD)

Sheet EV to Equity Value
A3: Enterprise Value to Equity Value | D3: ALL FIGURES ARE in MILLIONS (USD)
A5: Enterprise Value | B5: 467888.5
A6: Cash | B6: 24105
A7: Marketable Securities | B7: 417
A8: Short term debt | B8: 5983
A9: Long term debt | B9: 30651
A10: Equity Value | B10: =B5+B6+B7-B8-B9 -> 455776.5
A12: Shares Outstanding | B12: 2406.922
A13: Share Price | B13: =B10/B12 -> 189.36073

Sheet FULL DCF
B3: Discounted Cash Flow Full
B5: Growth rate | C5: 0.0225 | D5: Beta | F5: 0.35
B6: Cost of Debt | C6: 0.060334112 | D6: Market Return | F6: 0.1
B7: Tax Rate | C7: 0.2 | D7: Equity value | F7: 505728.2
B8: 10y Treasury | C8: 0.042 | D8: Debt value | F8: 36634
B12: Period | C12: 0 | D12: 1 | E12: 2 | F12: 3 | G12: 4 | H12: 5
B14: Free Cash Flows
B15: EBIT | D15: 19491.768 | E15: 20271.439 | F15: 20980.94 | G15: 21610.368 | H15: 22150.627
B16: Tax | D16: 0.2 | E16: 0.2 | F16: 0.2 | G16: 0.2 | H16: 0.2
B17: D&A | D17: 8075.1612 | E17: 8398.1677 | F17: 8692.1035 | G17: 8952.8666 | H17: 9176.6883
B18: CapEx | D18: 6033.1664 | E18: 6081.4318 | F18: 5994.5542 | G18: 5968.5778 | H18: 5801.3547
B19: Non-cash Work. Capital (inc) / dec | D19: 928.17945 | E19: 965.30663 | F19: 999.09236 | G19: 1029.0651 | H19: 1054.7918
B20: FCF | D20: =D15*(1-D16)+D17-D18-D19 -> 16707.23 | E20: =E15*(1-E16)+E17-E18-E19 -> 17568.581 | F20: =F15*(1-F16)+F17-F18-F19 -> 18483.209 | G20: =G15*(1-G16)+G17-G18-G19 -> 19243.518 | H20: =H15*(1-H16)+H17-H18-H19 -> 20041.043
B22: WACC
B23: Cost of Equity | C23: =C8+F5*(F6-C8) -> 0.0623
B24: D/D+E | C24: =F8/(F7+F8) -> 0.067545268
B25: E/D+E | C25: =F7/(F7+F8) -> 0.93245473
B26: WACC | C26: =C23*C25+C24*C6*(1-20%) -> 0.061352157
B28: Terminal Value
B30: Perpetuity Growth | H30: =(H20*(1+C5)/(C26-C5)) -> 527434.47
B32: Discounting
B33: Discount Factor | D33: =1/(1+$C26)^D12 -> 0.94219434 | E33: =1/(1+$C26)^E12 -> 0.88773018 | F33: =1/(1+$C26)^F12 -> 0.83641436 | G33: =1/(1+$C26)^G12 -> 0.78806488 | H33: =1/(1+$C26)^H12 -> 0.74251027
B34: PV of FCF | D34: =D33*D20 -> 15741.458 | E34: =E33*E20 -> 15596.159 | F34: =F33*F20 -> 15459.621 | G34: =G33*G20 -> 15165.141 | H34: =H33*H20 -> 14880.681
B35: PV of TV | H35: ='FULL DCF'!H30*'FULL DCF'!H33 -> 391625.52
B36: Enterprise Value | C36: =SUM(D34,E34,F34,G34,H34,H35) -> 468468.57
B38: Enterprise Value to Equity Value
B39: Cash | C39: 24105
B40: Marketable Securities | C40: 417
B41: Short term Debt | C41: 5983
B42: Long term Debt | C42: 30651
B43: Equity Value | C43: =C36+C39+C40-C41-C42 -> 456356.57
B45: Shares Outstanding | C45: 2406.922
B46: Implied Share Price | C46: =C43/C45 -> 189.60173

Sheet Income_Statement_FULL
B1: 2021 | C1: 2022 | D1: 2023 | E1: 2024
A2: Tax Effect Of Unusual Items | B2: -79.848 | C2: -162.932 | D2: -1035.23 | E2: -1121.765
A3: Tax Rate For Calcs | B3: 7.2e-08 | C3: 1.54e-07 | D3: 1.15e-07 | E3: 1.57e-07
A4: Normalized EBITDA | B4: 27860 | C4: 27663 | D4: 32322 | E4: 31926
A5: Total Unusual Items | B5: -1109 | C5: -1058 | D5: -9002 | E5: -7145
A6: Total Unusual Items Excluding Goodwill | B6: -1109 | C6: -1058 | D6: -9002 | E6: -7145
A7: Net Income From Continuing Operation Net Minority Interest | B7: 17801 | C7: 16370 | D7: 13326 | E7: 14066
A8: Reconciled Depreciation | B8: 7390 | C8: 6970 | D8: 7486 | E8: 7339
A9: Reconciled Cost Of Revenue | B9: 23402 | C9: 24596 | D9: 26553 | E9: 27471
A10: EBITDA | B10: 26751 | C10: 26605 | D10: 23320 | E10: 24781
A11: EBIT | B11: 19361 | C11: 19635 | D11: 15834 | E11: 17442
A12: Net Interest Income | B12: -130 | C12: 214 | D12: 489 | E12: 577
A13: Interest Expense | B13: 183 | C13: 276 | D13: 772 | E13: 755
... A50: Operating Revenue | B50: 78740 | C50: 79990 | D50: 85159 | E50: 88821

Sheet Cash_Flow_FULL
B1: 2020 | C1: 2021 | D1: 2022 | E1: 2023 | F1: 2024
A2: Free Cash Flow | C2: 19758 | D2: 17185 | E2: 17778 | F2: 18059
A3: Repurchase Of Capital Stock | C3: -3456 | D3: -6035 | E3: -5054 | F3: -2432
A4: Repayment Of Debt | C4: -2992 | D4: -8684 | E4: -24524 | F4: -11886
A5: Issuance Of Debt | C5: 2002 | D5: 16136 | E5: 21790 | F5: 21937
A6: Issuance Of Capital Stock | C6: 0 | D6: 0 | E6: 4241 | F6: 0
A7: Capital Expenditure | C7: -3652 | D7: -4009 | E7: -5013 | F7: -6207
A8: Interest Paid Supplemental Data | C8: 990 | D8: 982 | E8: 1836 | F8: 1990
A9: Income Tax Paid Supplemental Data | C9: 4768 | D9: 5223 | E9: 8574 | F9: 6714
A10: End Cash Position | C10: 14487 | D10: 14127 | E10: 21859 | F10: 24105
A11: Beginning Cash Position | C11: 13985 | D11: 14487 | E11: 14127 | F11: 21859
A12: Effect Of Exchange Rate Changes | C12: -178 | D12: -312 | E12: -112 | F12: -289
A13: Changes In Cash | C13: 680 | D13: -48 | E13: 7844 | F13: 2535
... A50: Changes In Account Receivables | C50: -2402 | D50: -1290 | E50: -624 | F50: -406
A51: Other Non Cash Items | B51: -1148 | E51: 483 | F51: 1841
A52: Stock Based Compensation | C52: 1135 | D52: 1138 | E52: 1162 | F52: 1176
A53: Provisionand Write Offof Assets | C53: -48 | D53: -17 | E53: 0 | F53: 11
A54: Asset Impairment Charge | C54: 989 | D54: 1216 | E54: 1295 | F54: 405
A55: Deferred Tax | C55: -2079 | D55: -1663 | E55: -4194 | F55: -2183
A56: Deferred Income Tax | C56: -2079 | D56: -1663 | E56: -4194 | F56: -2183
A57: Depreciation Amortization Depletion | C57: 7390 | D57: 6970 | E57: 7486 | F57: 7339
A58: Depreciation And Amortization | C58: 7390 | D58: 6970 | E58: 7486 | F58: 7339
A59: Operating Gains Losses | C59: -617 | D59: -380 | E59: -21101 | F59: -226
A60: Gain Loss On Sale Of Business | C60: 0 | D60: -380 | E60: -21101 | F60: -226
A61: Net Income From Continuing Operations | C61: 20878 | D61: 17941 | E61: 35153 | F61: 14066

Sheet Balance_Sheet_FULL
B1: 2020 | C1: 2021 | D1: 2022 | E1: 2023 | F1: 2024
A2: Treasury Shares Number | C2: 490.878 | D2: 506.246 | E2: 712.765 | F2: 712.921
A3: Ordinary Shares Number | C3: 2628.965 | D3: 2613.597 | E3: 2407.078 | F3: 2406.922
A4: Share Issued | C4: 3119.843 | D4: 3119.843 | E4: 3119.843 | F4: 3119.843
A5: Net Debt | C5: 19264 | D5: 26753 | E5: 7473 | F5: 12529
A6: Total Debt | C6: 33751 | D6: 39642 | E6: 29332 | F6: 36634
A7: Tangible Book Value | C7: -7615 | D7: 2268 | E7: -1959 | F7: -10328
A8: Invested Capital | C8: 107774 | D8: 116446 | E8: 98106 | F8: 108124
A9: Working Capital | C9: 15753 | D9: -508 | E9: 7213 | F9: 5572
A10: Net Tangible Assets | C10: -7615 | D10: 2268 | E10: -1959 | F10: -10328
A11: Common Stock Equity | C11: 74023 | D11: 76804 | E11: 68774 | F11: 71490
A12: Total Capitalization | C12: 104008 | D12: 103690 | E12: 94655 | F12: 102141
A13: Total Equity Gross Minority Interest | C13: 74023 | D13: 76804 | E13: 68774 | F13: 71490
... A17: Treasury Stock | C17: 39099 | D17: 41694 | E17: 75662 | F17: 75680
A18: Retained Earnings | B18: 113890 | C18: 123060 | D18: 128345 | E18: 153843
A19: Additional Paid In Capital | C19: 123060 | D19: 128345 | E19: 153843 | F19: 155791
A20: Capital Stock | C20: 3120 | D20: 3120 | E20: 3120 | F20: 3120
A21: Common Stock | C21: 3120 | D21: 3120 | E21: 3120 | F21: 3120
A22: Preferred Stock | C22: 0 | D22: 0 | E22: 0 | F22: 0
A23: Total Liabilities Net Minority Interest | C23: 107995 | D23: 110574 | E23: 98784 | F23: 108614
A24: Total Non Current Liabilities Net Minority Interest | C24: 62769 | D24: 54772 | E24: 52502 | F24: 58293
A25: Other Non Current Liabilities | C25: 10686 | D25: 10146 | E25: 13398 | F25: 17549
A26: Liabilities Heldfor Sale Non Current | D26: 2901 | E26: 0
A27: Employee Benefits | C27: 8898 | D27: 6542 | E27: 7149 | F27: 7255
A28: Tradeand Other Payables Non Current | C28: 5713 | D28: 4306 | E28: 2881 | F28: 390
A29: Non Current Deferred Liabilities | C29: 7487 | D29: 3991 | E29: 3193 | F29: 2448
A30: Non Current Deferred Taxes Liabilities | C30: 7487 | D30: 3991 | E30: 3193 | F30: 2448
A31: Long Term Debt And Capital Lease Obligation | C31: 29985 | D31: 26886 | E31: 25881 | F31: 30651
A32: Long Term Debt | C32: 29985 | D32: 26886 | E32: 25881 | F32: 30651
A33: Current Liabilities | C33: 45226 | D33: 55802 | E33: 46282 | F33: 50321
A34: Other Current Liabilities | D34: 3590
A35: Current Debt And Capital Lease Obligation | C35: 3766 | D35: 12756 | E35: 3451 | F35: 5983
A36: Current Debt | C36: 3766 | D36: 12756 | E36: 3451 | F36: 5983
A37: Pensionand Other Post Retirement Benefit Plans Current | C37: 3586 | D37: 3049 | E37: 3993 | F37: 4126
A38: Payables And Accrued Expenses | C38: 37874 | D38: 36407 | E38: 38838 | F38: 40212
A39: Current Accrued Expenses | C39: 25707 | D39: 24298 | E39: 26213 | F39: 26129
A40: Payables | C40: 12167 | D40: 12109 | E40: 12625 | F40: 14083
A41: Total Tax Payable | C41: 1112 | D41: 2220 | E41: 2993 | F41: 3772
A42: Income Tax Payable | C42: 1112 | D42: 2220 | E42: 2993 | F42: 3772
A43: Accounts Payable | C43: 11055 | D43: 9889 | E43: 9632 | F43: 10311
...
