Workbook

Sheet projectfinnman
P1: Method 1 : cost of equity using CAPM
A2: India Cements Limited | E2: Nifty 50(Proxy for Market Return) | I2: Nifty 50 Small Cap(Proxy for Small Cap Returns)
A3: Date | B3: Price | C3: change | D3: Change % | E3: Date | F3: Price | G3: change | H3: Change % | I3: Date | J3: Price | K3: Change | L3: Change % | M3: Excess Return from the market | O3: beta | P3: beta(regression) | S3: =(F4/F746)^(1/3) -> 1.1451568
A4: 45379 | B4: 212.4 | C4: =B4/B5-1 -> 0 | D4: 0 | E4: 45379 | F4: 22326.9 | G4: =F4/F5-1 -> 0.0091870012 | H4: 0.0092 | I4: 45379 | J4: 7029.95 | K4: =J4/J5-1 -> 0.00062628549 | L4: =K4/K5-1 -> -0.90051252 | M4: =K4-0.07 -> -0.069373715 | O4: =_xlfn.COVARIANCE.P(C4:C745,G4:G745)/_xlfn.VAR.P(G4:G745) -> 1.4987053 | P4: 1.4987053 | R4: Erm | S4: =S3-1 -> 0.14515679 | T4: Rf | U4: 0.065991 | AN4: Used for Beta analysis
A5: 45378 | B5: 212.4 | C5: =B5/B6-1 -> 0.015539087 | D5: 0.0155 | E5: 45378 | F5: 22123.65 | G5: =F5/F6-1 -> 0.0054056633 | H5: 0.0054 | I5: 45378 | J5: 7025.55 | K5: =J5/J6-1 -> 0.0062951186 | L5: =K5/K6-1 -> 3.34519 | M5: =K5-0.07 -> -0.063704881 | S5: 0.1452 | U5: =U4 -> 0.065991 | AO5: Coefficients | AP5: Standard Error | AQ5: t Stat | AR5: P-value | AS5: Lower 95% | AT5: Upper 95% | AU5: Lower 95.0% | AV5: Upper 95.0%
A6: 45377 | B6: 209.15 | C6: =B6/B7-1 -> 0.010142478 | D6: 0.0101 | E6: 45377 | F6: 22004.7 | G6: =F6/F7-1 -> -0.004165771 | H6: -0.0042 | I6: 45377 | J6: 6981.6 | K6: =J6/J7-1 -> 0.0014487556 | L6: =K6/K7-1 -> -0.79320133 | M6: =K6-0.07 -> -0.068551244 | AD6: India Cements Ltd: Significantly higher cost of equity (~18-20%) compared to the industry average (~10-12%). | AN6: Intercept | AO6: -0.00021338915 | AP6: 0.00087123836 | AQ6: -0.24492625 | AR6: 0.80658144 | AS6: -0.0019237825 | AT6: 0.0014970042 | AU6: -0.0019237825 | AV6: 0.0014970042
A7: 45373 | B7: 207.05 | C7: =B7/B8-1 -> 0.016445754 | D7: 0.0164 | E7: 45373 | F7: 22096.75 | G7: =F7/F8-1 -> 0.0038524529 | H7: 0.0039 | I7: 45373 | J7: 6971.5 | K7: =J7/J8-1 -> 0.0070056334 | L7: =K7/K8-1 -> -0.69994644 | M7: =K7-0.07 -> -0.062994367 | R7: premium | S7: =S4-U5 -> 0.079165794 | AN7: X Variable 1 | AO7: 1.4987053 | AP7: 0.10066425 | AQ7: 14.888157 | AR7: 4.8099353e-44 | AS7: 1.3010837 | AT7: 1.6963268 | AU7: 1.3010837 | AV7: 1.6963268
A8: 45372 | B8: 203.7 | C8: =B8/B9-1 -> 0.036113937 | D8: 0.0361 | E8: 45372 | F8: 22011.95 | G8: =F8/F9-1 -> 0.0079147034 | H8: 0.0079 | I8: 45372 | J8: 6923 | K8: =J8/J9-1 -> 0.023347943 | L8: =K8/K9-1 -> 262.22665 | M8: =K8-0.07 -> -0.046652057 | R8: beta premium | S8: =S7*O4 -> 0.11864619
A9: 45371 | B9: 196.6 | C9: =B9/B10-1 -> -0.011812013 | D9: -0.0118 | E9: 45371 | F9: 21839.1 | G9: =F9/F10-1 -> 0.00099232495 | H9: 0.001 | I9: 45371 | J9: 6765.05 | K9: =J9/J10-1 -> 8.8699007e-05 | L9: =K9/K10-1 -> -1.0085394 | M9: =K9-0.07 -> -0.069911301 | R9: Ke(ERi) | S9: =S8+U5 -> 0.18463719 | T9: =S9*100 -> 18.463719
A10: 45370 | B10: 198.95 | C10: =B10/B11-1 -> -0.02618698 | D10: -0.0262 | E10: 45370 | F10: 21817.45 | G10: =F10/F11-1 -> -0.010802196 | H10: -0.0108 | I10: 45370 | J10: 6764.45 | K10: =J10/J11-1 -> -0.010387026 | L10: =K10/K11-1 -> 1.0476898 | M10: =K10-0.07 -> -0.080387026 | R10: (cost of equity) | T10: 0.18463719
A11: 45369 | B11: 204.3 | C11: =B11/B12-1 -> -0.0034146341 | D11: -0.0034 | E11: 45369 | F11: 22055.7 | G11: =F11/F12-1 -> 0.0014688955 | H11: 0.0015 | I11: 45369 | J11: 6835.45 | K11: =J11/J12-1 -> -0.0050725587 | L11: =K11/K12-1 -> -2.2668253 | M11: =K11-0.07 -> -0.075072559
A12: 45366 | B12: 205 | C12: =B12/B13-1 -> 0.0039177277 | D12: 0.0039 | E12: 45366 | F12: 22023.35 | G12: =F12/F13-1 -> -0.0055674334 | H12: -0.0056 | I12: 45366 | J12: 6870.3 | K12: =J12/J13-1 -> 0.0040041503 | L12: =K12/K13-1 -> -0.88228047 | M12: =K12-0.07 -> -0.06599585
A13: 45365 | B13: 204.2 | C13: =B13/B14-1 -> 0.041571028 | D13: 0.0416 | E13: 45365 | F13: 22146.65 | G13: =F13/F14-1 -> 0.0067711624 | H13: 0.0068 | I13: 45365 | J13: 6842.9 | K13: =J13/J14-1 -> 0.034014325 | L13: =K13/K14-1 -> -1.6472823 | M13: =K13-0.07 -> -0.035985675 | R13: Cost of Equity Using CAPM Model
A14: 45364 | B14: 196.05 | C14: =B14/B15-1 -> -0.076760066 | D14: -0.0768 | E14: 45364 | F14: 21997.7 | G14: =F14/F15-1 -> -0.015132725 | H14: -0.0151 | I14: 45364 | J14: 6617.8 | K14: =J14/J15-1 -> -0.052549446 | L14: =K14/K15-1 -> 2.2167736 | M14: =K14-0.07 -> -0.12254945
A15: 45363 | B15: 212.35 | C15: =B15/B16-1 -> -0.034772727 | D15: -0.0348 | E15: 45363 | F15: 22335.7 | G15: =F15/F16-1 -> 0.00013657134 | H15: 0.0001 | I15: 45363 | J15: 6984.85 | K15: =J15/J16-1 -> -0.016336072 | L15: =K15/K16-1 -> -0.17614565 | M15: =K15-0.07 -> -0.086336072
A16: 45362 | B16: 220 | C16: =B16/B17-1 -> -0.024606517 | D16: -0.0246 | E16: 45362 | F16: 22332.65 | G16: =F16/F17-1 -> -0.0071531617 | H16: -0.0072 | I16: 45362 | J16: 7100.85 | K16: =J16/J17-1 -> -0.019828836 | L16: =K16/K17-1 -> -3.1452051 | M16: =K16-0.07 -> -0.089828836
A17: 45358 | B17: 225.55 | C17: =B17/B18-1 -> 0.0089465444 | D17: 0.0089 | E17: 45358 | F17: 22493.55 | G17: =F17/F18-1 -> 0.00086766738 | H17: 0.0009 | I17: 45358 | J17: 7244.5 | K17: =J17/J18-1 -> 0.0092433287 | L17: =K17/K18-1 -> -1.4424787 | M17: =K17-0.07 -> -0.060756671
A18: 45357 | B18: 223.55 | C18: =B18/B19-1 -> -0.020805957 | D18: -0.0208 | E18: 45357 | F18: 22474.05 | G18: =F18/F19-1 -> 0.0052669717 | H18: 0.0053 | I18: 45357 | J18: 7178.15 | K18: =J18/J19-1 -> -0.020889883 | L18: =K18/K19-1 -> 0.93886108 | M18: =K18-0.07 -> -0.090889883
A19: 45356 | B19: 228.3 | C19: =B19/B20-1 -> -0.016795866 | D19: -0.0168 | E19: 45356 | F19: 22356.3 | G19: =F19/F20-1 -> -0.0022003428 | H19: -0.0022 | I19: 45356 | J19: 7331.3 | K19: =J19/J20-1 -> -0.010774306 | L19: =K19/K20-1 -> 2.0296779 | M19: =K19-0.07 -> -0.080774306
A20: 45355 | B20: 232.2 | C20: =B20/B21-1 -> -0.0030055818 | D20: -0.003 | E20: 45355 | F20: 22405.6 | G20: =F20/F21-1 -> 0.0012154578 | H20: 0.0012 | I20: 45355 | J20: 7411.15 | K20: =J20/J21-1 -> -0.0035562547 | L20: =K20/K21-1 -> -1.4540562 | M20: =K20-0.07 -> -0.073556255 | AD20: India Cements Ltd: Beta is well above the industry average (>1.5 vs. ~1).
A21: 45353 | B21: 232.9 | C21: =B21/B22-1 -> 0.0075708414 | D21: 0.0076 | E21: 45353 | F21: 22378.4 | G21: =F21/F22-1 -> 0.0017749426 | H21: 0.0018 | I21: 45353 | J21: 7437.6 | K21: =J21/J22-1 -> 0.0078321906 | L21: =K21/K22-1 -> 1.0454538 | M21: =K21-0.07 -> -0.062167809
A22: 45352 | B22: 231.15 | C22: =B22/B23-1 -> 0.010050251 | D22: 0.0101 | E22: 45352 | F22: 22338.75 | G22: =F22/F23-1 -> 0.016192205 | H22: 0.0162 | I22: 45352 | J22: 7379.8 | K22: =J22/J23-1 -> 0.0038290724 | L22: =K22/K23-1 -> -0.21970651 | M22: =K22-0.07 -> -0.066170928
A23: 45351 | B23: 228.85 | C23: =B23/B24-1 -> 0.01914941 | D23: 0.0191 | E23: 45351 | F23: 21982.8 | G23: =F23/F24-1 -> 0.0014418379 | H23: 0.0014 | I23: 45351 | J23: 7351.65 | K23: =J23/J24-1 -> 0.0049072207 | L23: =K23/K24-1 -> -1.2389359 | M23: =K23-0.07 -> -0.065092779
A24: 45350 | B24: 224.55 | C24: =B24/B25-1 -> -0.041817794 | D24: -0.0418 | E24: 45350 | F24: 21951.15 | G24: =F24/F25-1 -> -0.011135963 | H24: -0.0111 | I24: 45350 | J24: 7315.75 | K24: =J24/J25-1 -> -0.020537812 | L24: =K24/K25-1 -> 13.02967 | M24: =K24-0.07 -> -0.090537812
A25: 45349 | B25: 234.35 | C25: =B25/B26-1 -> -0.019866165 | D25: -0.0199 | E25: 45349 | F25: 22198.35 | G25: =F25/F26-1 -> 0.0034490474 | H25: 0.0034 | I25: 45349 | J25: 7469.15 | K25: =J25/J26-1 -> -0.0014638842 | L25: =K25/K26-1 -> -0.68068416 | M25: =K25-0.07 -> -0.071463884
A26: 45348 | B26: 239.1 | C26: =B26/B27-1 -> -0.024678768 | D26: -0.0247 | E26: 45348 | F26: 22122.05 | G26: =F26/F27-1 -> -0.0040809987 | H26: -0.0041 | I26: 45348 | J26: 7480.1 | K26: =J26/J27-1 -> -0.0045844395 | L26: =K26/K27-1 -> -3.9025886 | M26: =K26-0.07 -> -0.07458444
A27: 45345 | B27: 245.15 | C27: =B27/B28-1 -> -0.012885041 | D27: -0.0129 | E27: 45345 | F27: 22212.7 | G27: =F27/F28-1 -> -0.00021379591 | H27: -0.0002 | I27: 45345 | J27: 7514.55 | K27: =J27/J28-1 -> 0.0015794314 | L27: =K27/K28-1 -> -0.81228231 | M27: =K27-0.07 -> -0.068420569
A28: 45344 | B28: 248.35 | C28: =B28/B29-1 -> 0.023069001 | D28: 0.0231 | E28: 45344 | F28: 22217.45 | G28: =F28/F29-1 -> 0.007363393 | H28: 0.0074 | I28: 45344 | J28: 7502.7 | K28: =J28/J29-1 -> 0.0084138654 | L28: =K28/K29-1 -> -1.9497672 | M28: =K28-0.07 -> -0.061586135
A29: 45343 | B29: 242.75 | C29: =B29/B30-1 -> -0.00041177682 | D29: -0.0004 | E29: 45343 | F29: 22055.05 | G29: =F29/F30-1 -> -0.0063927702 | H29: -0.0064 | I29: 45343 | J29: 7440.1 | K29: =J29/J30-1 -> -0.0088588709 | L29: =K29/K30-1 -> 0.69667613 | M29: =K29-0.07 -> -0.078858871
A30: 45342 | B30: 242.85 | C30: =B30/B31-1 -> 0.0064235392 | D30: 0.0064 | E30: 45342 | F30: 22196.95 | G30: =F30/F31-1 -> 0.0033766909 | H30: 0.0034 | I30: 45342 | J30: 7506.6 | K30: =J30/J31-1 -> -0.0052213093 | L30: =K30/K31-1 -> -5.9197787 | M30: =K30-0.07 -> -0.075221309
A31: 45341 | B31: 241.3 | C31: =B31/B32-1 -> -0.0084240805 | D31: -0.0084 | E31: 45341 | F31: 22122.25 | G31: =F31/F32-1 -> 0.0036999732 | H31: 0.0037 | I31: 45341 | J31: 7546 | K31: =J31/J32-1 -> 0.0010612895 | L31: =K31/K32-1 -> -0.56862886 | M31: =K31-0.07 -> -0.068938711
A32: 45338 | B32: 243.35 | C32: =B32/B33-1 -> 0.032894737 | D32: 0.0329 | E32: 45338 | F32: 22040.7 | G32: =F32/F33-1 -> 0.0059308787 | H32: 0.0059 | I32: 45338 | J32: 7538 | K32: =J32/J33-1 -> 0.00246027 | L32: =K32/K33-1 -> -0.82551144 | M32: =K32-0.07 -> -0.06753973
... A36: 45334 | B36: 235.15 | C36: =B36/B37-1 -> -0.048745955 | D36: -0.0487 | E36: 45334 | F36: 21616.05 | G36: =F36/F37-1 -> -0.0076414553 | H36: -0.0076 | I36: 45334 | J36: 7274.15 | K36: =J36/J37-1 -> -0.035501664 | L36: =K36/K37-1 -> 1.8376995 | M36: =K36-0.07 -> -0.10550166
A37: 45331 | B37: 247.2 | C37: =B37/B38-1 -> 0.041499895 | D37: 0.0415 | E37: 45331 | F37: 21782.5 | G37: =F37/F38-1 -> 0.0029721958 | H37: 0.003 | I37: 45331 | J37: 7541.9 | K37: =J37/J38-1 -> -0.01251072 | L37: =K37/K38-1 -> 1.114821 | M37: =K37-0.07 -> -0.08251072 | R37: COST OF DEBT
A38: 45330 | B38: 237.35 | C38: =B38/B39-1 -> -0.0098039216 | D38: -0.0098 | E38: 45330 | F38: 21717.95 | G38: =F38/F39-1 -> -0.0096919815 | H38: -0.0097 | I38: 45330 | J38: 7637.45 | K38: =J38/J39-1 -> -0.0059157349 | L38: =K38/K39-1 -> -1.7618208 | M38: =K38-0.07 -> -0.075915735 | R38: Year | S38: 2021 | T38: 2022 | U38: 2023 | V38: 2024
A39: 45329 | B39: 239.7 | C39: =B39/B40-1 -> -0.0056004978 | D39: -0.0056 | E39: 45329 | F39: 21930.5 | G39: =F39/F40-1 -> 5.0160971e-05 | H39: 0.0001 | I39: 45329 | J39: 7682.9 | K39: =J39/J40-1 -> 0.0077652583 | L39: =K39/K40-1 -> -0.16745298 | M39: =K39-0.07 -> -0.062234742 | R39: Total Debt (Crores) | S39: =463.64+1979.81 -> 2443.45 | T39: =1134.45+1928.7 -> 3063.15 | U39: =1119.32+1799.24 -> 2918.56 | V39: =1185.97+1415.26 -> 2601.23
A40: 45328 | B40: 241.05 | C40: =B40/B41-1 -> 0.030788967 | D40: 0.0308 | E40: 45328 | F40: 21929.4 | G40: =F40/F41-1 -> 0.007243348 | H40: 0.0072 | I40: 45328 | J40: 7623.7 | K40: =J40/J41-1 -> 0.0093271108 | L40: =K40/K41-1 -> 1.4713067 | M40: =K40-0.07 -> -0.060672889 | R40: Interest Paid(crores) | S40: 271 | T40: 198 | U40: 242 | V40: 244
A41: 45327 | B41: 233.85 | C41: =B41/B42-1 -> -0.026436303 | D41: -0.0264 | E41: 45327 | F41: 21771.7 | G41: =F41/F42-1 -> -0.0037567837 | H41: -0.0038 | I41: 45327 | J41: 7553.25 | K41: =J41/J42-1 -> 0.0037741616 | L41: =K41/K42-1 -> -0.60007835 | M41: =K41-0.07 -> -0.066225838 | R41: Average Interest rate(%) | S41: 0.0935 | T41: 0.0683 | U41: 0.0835 | V41: 0.0842 | AD41: India Cements Ltd: Lower WACC (~10-12%) than the industry average (~15-18%).
A42: 45324 | B42: 240.2 | C42: =B42/B43-1 -> -0.0082576383 | D42: -0.0083 | E42: 45324 | F42: 21853.8 | G42: =F42/F43-1 -> 0.0072059159 | H42: 0.0072 | I42: 45324 | J42: 7524.85 | K42: =J42/J43-1 -> 0.0094372527 | L42: =K42/K43-1 -> 2.6738088 | M42: =K42-0.07 -> -0.060562747 | R42: Taxable income(Crores) | S42: 322.71 | T42: 54.03 | U42: -406.91 | V42: -254.67
A43: 45323 | B43: 242.2 | C43: =B43/B44-1 -> -0.07345065 | D43: -0.0735 | E43: 45323 | F43: 21697.45 | G43: =F43/F44-1 -> -0.0013003033 | H43: -0.0013 | I43: 45323 | J43: 7454.5 | K43: =J43/J44-1 -> 0.0025687925 | L43: =K43/K44-1 -> -0.89158681 | M43: =K43-0.07 -> -0.067431207 | R43: Tax Paid (Crores) | S43: =322.71-222.04 -> 100.67 | T43: =T42-38.98 -> 15.05 | U43: 0 | V43: 0
...

Sheet Fama French Model
B1: Mkt-RF | C1: SMB | D1: HML | E1: RF | F1: Change | G1: Excess Return from the market | J1: Mkt-RF | K1: SMB | L1: HML | M1: RF
A2: 20210401 | B2: 1.27 | C2: 0.29 | D2: -0.02 | E2: 0 | F2: 0.00062628549 | G2: -0.069373715 | J2: 1.27 | K2: 0.29 | L2: -0.02
A3: 20210405 | B3: 1.27 | C3: -0.57 | D3: -0.72 | E3: 0 | F3: 0.0062951186 | G3: -0.063704881 | J3: =AVERAGE(B2:B743) -> 0.029245283 | K3: =AVERAGE(C2:C743) -> -0.033679245 | L3: =AVERAGE(D2:D743) -> 0.022493261 | M3: =AVERAGE(E2:E743) -> 0.0098045822
A4: 20210406 | B4: 0.01 | C4: -0.32 | D4: 0.1 | E4: 0 | F4: 0.0014487556 | G4: -0.068551244
A5: 20210407 | B5: -0.12 | C5: -1.6 | D5: 0.3 | E5: 0 | F5: 0.0070056334 | G5: -0.062994367
A6: 20210408 | B6: 0.62 | C6: 0.6 | D6: -1.16 | E6: 0 | F6: 0.023347943 | G6: -0.046652057
A7: 20210409 | B7: 0.65 | C7: -0.64 | D7: 0.13 | E7: 0 | F7: 8.8699007e-05 | G7: -0.069911301 | J7: Cost of equity | P7: Coefficients | Q7: Standard Error | R7: t Stat | S7: P-value | T7: Lower 95% | U7: Upper 95% | V7: Lower 95.0% | W7: Upper 95.0%
A8: 20210412 | B8: -0.05 | C8: -0.6 | D8: 0.58 | E8: 0 | F8: -0.010387026 | G8: -0.080387026 | J8: =M3+(J2*J3+K2*K3+L2*L3)*756 -> 20.36485 | K8: % | O8: Intercept | P8: -0.069262188 | Q8: 0.0004605728 | R8: -150.38271 | S8: 0 | T8: -0.070166379 | U8: -0.068357997 | V8: -0.070166379 | W8: -0.068357997
A9: 20210413 | B9: 0.41 | C9: -0.3 | D9: -1.58 | E9: 0 | F9: -0.0050725587 | G9: -0.075072559 | O9: 1.27 | P9: 0.00061853941 | Q9: 0.00044850695 | R9: 1.3791077 | S9: 0.1682799 | T9: -0.00026196406 | U9: 0.0014990429 | V9: -0.00026196406 | W9: 0.0014990429
A10: 20210414 | B10: -0.35 | C10: 0.78 | D10: 1.42 | E10: 0 | F10: 0.0040041503 | G10: -0.06599585 | O10: 0.29 | P10: -0.00066866717 | Q10: 0.0006959759 | R10: -0.96076196 | S10: 0.33698696 | T10: -0.0020349987 | U10: 0.00069766438 | V10: -0.0020349987 | W10: 0.00069766438
A11: 20210415 | B11: 1.04 | C11: -0.43 | D11: -1.18 | E11: 0 | F11: 0.034014325 | G11: -0.035985675 | O11: -0.02 | P11: 0.0008055024 | Q11: 0.00049467238 | R11: 1.6283553 | S11: 0.10387693 | T11: -0.00016563248 | U11: 0.0017766373 | V11: -0.00016563248 | W11: 0.0017766373
A12: 20210416 | B12: 0.27 | C12: -0.35 | D12: 0.64 | E12: 0 | F12: -0.052549446 | G12: -0.12254945
A13: 20210419 | B13: -0.73 | C13: -0.77 | D13: 0.78 | E13: 0 | F13: -0.016336072 | G13: -0.086336072 | I13: Method 5: calculate the cost of equity using the Fama French Model
A14: 20210420 | B14: -0.94 | C14: -1.18 | D14: -1.57 | E14: 0 | F14: -0.019828836 | G14: -0.089828836
A15: 20210421 | B15: 1.11 | C15: 1.38 | D15: 0.11 | E15: 0 | F15: 0.0092433287 | G15: -0.060756671
A16: 20210422 | B16: -0.77 | C16: 0.65 | D16: -0.78 | E16: 0 | F16: -0.020889883 | G16: -0.090889883
A17: 20210423 | B17: 1.26 | C17: 0.74 | D17: 0.7 | E17: 0 | F17: -0.010774306 | G17: -0.080774306
A18: 20210426 | B18: 0.43 | C18: 0.86 | D18: -0.48 | E18: 0 | F18: -0.0035562547 | G18: -0.073556255
A19: 20210427 | B19: -0.03 | C19: -0.16 | D19: 0.86 | E19: 0 | F19: 0.0078321906 | G19: -0.062167809
A20: 20210428 | B20: -0.06 | C20: 0.19 | D20: 0.2 | E20: 0 | F20: 0.0038290724 | G20: -0.066170928
A21: 20210429 | B21: 0.39 | C21: -1.13 | D21: 1.07 | E21: 0 | F21: 0.0049072207 | G21: -0.065092779
A22: 20210430 | B22: -0.83 | C22: -0.42 | D22: -0.32 | E22: 0 | F22: -0.020537812 | G22: -0.090537812
A23: 20210503 | B23: 0.17 | C23: 0.46 | D23: 1.7 | E23: 0 | F23: -0.0014638842 | G23: -0.071463884
A24: 20210504 | B24: -0.89 | C24: -0.75 | D24: 1.99 | E24: 0 | F24: -0.0045844395 | G24: -0.07458444
A25: 20210505 | B25: -0.05 | C25: -0.46 | D25: 1.33 | E25: 0 | F25: 0.0015794314 | G25: -0.068420569
... A743: 20240313 | B743: -0.14 | C743: 0.3 | D743: -0.04 | E743: 0.021 | F743: -0.013496012 | G743: -0.083496012
G744: -0.065991

Sheet ultrattech
A1: Date | B1: Price | C1: change | D1: Change % | E1: Date | F1: Price | G1: change | H1: Change % | I1: beta | J1: beta(regression) | M1: =(F2/F744)^(1/3) -> 1.1451568
A2: 45379 | B2: 9749.15 | C2: =B2/B3-1 -> 0.013061844 | D2: 0.0131 | E2: 45379 | F2: 22326.9 | G2: =F2/F3-1 -> 0.0091870012 | H2: 0.0092 | I2: =_xlfn.COVARIANCE.P(C2:C743,G2:G743)/_xlfn.VAR.P(G2:G743) -> 0.91908624 | J2: 1.4987053 | L2: Erm | M2: =M1-1 -> 0.14515679 | N2: Rf | O2: 0.065991
A3: 45378 | B3: 9623.45 | C3: =B3/B4-1 -> 0.0023696189 | D3: 0.0024 | E3: 45378 | F3: 22123.65 | G3: =F3/F4-1 -> 0.0054056633 | H3: 0.0054 | M3: 0.1452 | O3: =O2 -> 0.065991
A4: 45377 | B4: 9600.7 | C4: =B4/B5-1 -> -0.0083714205 | D4: -0.0084 | E4: 45377 | F4: 22004.7 | G4: =F4/F5-1 -> -0.004165771 | H4: -0.0042
A5: 45373 | B5: 9681.75 | C5: =B5/B6-1 -> 0.0084368409 | D5: 0.0084 | E5: 45373 | F5: 22096.75 | G5: =F5/F6-1 -> 0.0038524529 | H5: 0.0039 | L5: premium | M5: =M2-O3 -> 0.079165794
A6: 45372 | B6: 9600.75 | C6: =B6/B7-1 -> 0.012251504 | D6: 0.0123 | E6: 45372 | F6: 22011.95 | G6: =F6/F7-1 -> 0.0079147034 | H6: 0.0079 | L6: beta premium | M6: =M5*I2 -> 0.072760192
A7: 45371 | B7: 9484.55 | C7: =B7/B8-1 -> 0.0033110306 | D7: 0.0033 | E7: 45371 | F7: 21839.1 | G7: =F7/F8-1 -> 0.00099232495 | H7: 0.001 | L7: Ke(ERi) | M7: =M6+O3 -> 0.13875119 | N7: =M7*100 -> 13.875119
A8: 45370 | B8: 9453.25 | C8: =B8/B9-1 -> -0.016449302 | D8: -0.0164 | E8: 45370 | F8: 21817.45 | G8: =F8/F9-1 -> -0.010802196 | H8: -0.0108 | L8: (cost of equity) | N8: =M7 -> 0.13875119
A9: 45369 | B9: 9611.35 | C9: =B9/B10-1 -> -0.0022423038 | D9: -0.0022 | E9: 45369 | F9: 22055.7 | G9: =F9/F10-1 -> 0.0014688955 | H9: 0.0015
A10: 45366 | B10: 9632.95 | C10: =B10/B11-1 -> -0.0066000134 | D10: -0.0066 | E10: 45366 | F10: 22023.35 | G10: =F10/F11-1 -> -0.0055674334 | H10: -0.0056
A11: 45365 | B11: 9696.95 | C11: =B11/B12-1 -> 0.010778075 | D11: 0.0108 | E11: 45365 | F11: 22146.65 | G11: =F11/F12-1 -> 0.0067711624 | H11: 0.0068
A12: 45364 | B12: 9593.55 | C12: =B12/B13-1 -> -0.0022827726 | D12: -0.0023 | E12: 45364 | F12: 21997.7 | G12: =F12/F13-1 -> -0.015132725 | H12: -0.0151
A13: 45363 | B13: 9615.5 | C13: =B13/B14-1 -> -0.0084966848 | D13: -0.0085 | E13: 45363 | F13: 22335.7 | G13: =F13/F14-1 -> 0.00013657134 | H13: 0.0001
A14: 45362 | B14: 9697.9 | C14: =B14/B15-1 -> 0.0025586288 | D14: 0.0026 | E14: 45362 | F14: 22332.65 | G14: =F14/F15-1 -> -0.0071531617 | H14: -0.0072
A15: 45358 | B15: 9673.15 | C15: =B15/B16-1 -> 0.0033295129 | D15: 0.0033 | E15: 45358 | F15: 22493.55 | G15: =F15/F16-1 -> 0.00086766738 | H15: 0.0009
A16: 45357 | B16: 9641.05 | C16: =B16/B17-1 -> -0.020054176 | D16: -0.0201 | E16: 45357 | F16: 22474.05 | G16: =F16/F17-1 -> 0.0052669717 | H16: 0.0053
A17: 45356 | B17: 9838.35 | C17: =B17/B18-1 -> -0.014035316 | D17: -0.014 | E17: 45356 | F17: 22356.3 | G17: =F17/F18-1 -> -0.0022003428 | H17: -0.0022
A18: 45355 | B18: 9978.4 | C18: =B18/B19-1 -> -0.012660357 | D18: -0.0127 | E18: 45355 | F18: 22405.6 | G18: =F18/F19-1 -> 0.0012154578 | H18: 0.0012
A19: 45353 | B19: 10106.35 | C19: =B19/B20-1 -> -0.0028760298 | D19: -0.0029 | E19: 45353 | F19: 22378.4 | G19: =F19/F20-1 -> 0.0017749426 | H19: 0.0018
A20: 45352 | B20: 10135.5 | C20: =B20/B21-1 -> 0.024574421 | D20: 0.0246 | E20: 45352 | F20: 22338.75 | G20: =F20/F21-1 -> 0.016192205 | H20: 0.0162
... A34: 45334 | B34: 9963.85 | C34: =B34/B35-1 -> 0.0018198728 | D34: 0.0018 | E34: 45334 | F34: 21616.05 | G34: =F34/F35-1 -> -0.0076414553 | H34: -0.0076
A35: 45331 | B35: 9945.75 | C35: =B35/B36-1 -> -0.0051912199 | D35: -0.0052 | E35: 45331 | F35: 21782.5 | G35: =F35/F36-1 -> 0.0029721958 | H35: 0.003 | L35: COST OF DEBT
A36: 45330 | B36: 9997.65 | C36: =B36/B37-1 -> -0.022378135 | D36: -0.0224 | E36: 45330 | F36: 21717.95 | G36: =F36/F37-1 -> -0.0096919815 | H36: -0.0097 | L36: Year | M36: 2021 | N36: 2022 | O36: 2023 | P36: 2024
A37: 45329 | B37: 10226.5 | C37: =B37/B38-1 -> 0.017688767 | D37: 0.0177 | E37: 45329 | F37: 21930.5 | G37: =F37/F38-1 -> 5.0160971e-05 | H37: 0.0001 | L37: Total Debt (Crores) | M37: =0.32*11754 -> 3761.28 | N37: =0.33*11548 -> 3810.84 | O37: =10790*0.17 -> 1834.3 | P37: =13282*0.06 -> 796.92
A38: 45328 | B38: 10048.75 | C38: =B38/B39-1 -> 0.013351687 | D38: 0.0134 | E38: 45328 | F38: 21929.4 | G38: =F38/F39-1 -> 0.007243348 | H38: 0.0072 | L38: Interest Paid(crores) | M38: 1259 | N38: 798 | O38: 756 | P38: 867
A39: 45327 | B39: 9916.35 | C39: =B39/B40-1 -> -0.018042194 | D39: -0.018 | E39: 45327 | F39: 21771.7 | G39: =F39/F40-1 -> -0.0037567837 | H39: -0.0038 | L39: Average Interest rate(%) | M39: =M38/M37 -> 0.33472648 | N39: =N38/N37 -> 0.20940265 | O39: =O38/O37 -> 0.41214632 | P39: =P38/P37 -> 1.0879386
A40: 45324 | B40: 10098.55 | C40: =B40/B41-1 -> 0.017763019 | D40: 0.0178 | E40: 45324 | F40: 21853.8 | G40: =F40/F41-1 -> 0.0072059159 | H40: 0.0072 | L40: Taxable income(Crores) | M40: 8060 | N40: 8293 | O40: 7262 | P40: 9388
A41: 45323 | B41: 9922.3 | C41: =B41/B42-1 -> -0.024101659 | D41: -0.0241 | E41: 45323 | F41: 21697.45 | G41: =F41/F42-1 -> -0.0013003033 | H41: -0.0013 | L41: Tax Paid (Crores) | M41: 2554 | N41: 1227 | O41: 2310 | P41: 2411 | S41: 0.086
A42: 45322 | B42: 10167.35 | C42: =B42/B43-1 -> 0.020449436 | D42: 0.0204 | E42: 45322 | F42: 21725.7 | G42: =F42/F43-1 -> 0.0094600434 | H42: 0.0095 | L42: Tax rate | M42: =M41/M40 -> 0.31687345 | N42: =N41/N40 -> 0.14795611 | O42: =O41/O40 -> 0.31809419 | P42: =P41/P40 -> 0.25681721 | R42: after tax cost of debt | S42: =S41*100 -> 8.6 | T42: %
A43: 45321 | B43: 9963.6 | C43: =B43/B44-1 -> -0.030216906 | D43: -0.0302 | E43: 45321 | F43: 21522.1 | G43: =F43/F44-1 -> -0.0099136979 | H43: -0.0099 | L43: After Tax cost of debt | M43: =M39*(1-M42) -> 0.22866054 | N43: =N39*(1-N42) -> 0.17842025 | O43: =O39*(1-O42) -> 0.28104497 | P43: =P39*(1-P42) -> 0.80853721 | R43: (average)
A44: 45320 | B44: 10274.05 | C44: =B44/B45-1 -> 0.030563678 | D44: 0.0306 | E44: 45320 | F44: 21737.6 | G44: =F44/F45-1 -> 0.018030591 | H44: 0.018 | L44: Total Equity (crores) | M44: 289 | N44: 289 | O44: 289 | P44: 289
A45: 45316 | B45: 9969.35 | C45: =B45/B46-1 -> -0.0021170112 | D45: -0.0021 | E45: 45316 | F45: 21352.6 | G45: =F45/F46-1 -> -0.0047240718 | H45: -0.0047 | L45: weight of debt | M45: =M37/(M37+M38) -> 0.74921718 | N45: =N37/(N37+N38) -> 0.82685448 | O45: =O37/(O37+O38) -> 0.70814191 | P45: =P37/(P37+P38) -> 0.4789413
A46: 45315 | B46: 9990.5 | C46: =B46/B47-1 -> 0.016224189 | D46: 0.0162 | E46: 45315 | F46: 21453.95 | G46: =F46/F47-1 -> 0.010130045 | H46: 0.0101 | L46: weight of debt(%) | M46: =M45*100 -> 74.921718 | N46: =N45*100 -> 82.685448 | O46: =O45*100 -> 70.814191 | P46: =P45*100 -> 47.89413
A47: 45314 | B47: 9831 | C47: =B47/B48-1 -> -0.016644328 | D47: -0.0166 | E47: 45314 | F47: 21238.8 | G47: =F47/F48-1 -> -0.01543682 | H47: -0.0154 | L47: weight of equity | M47: =1-M45 -> 0.25078282 | N47: =1-N45 -> 0.17314552 | O47: =1-O45 -> 0.29185809 | P47: =1-P45 -> 0.5210587
A48: 45311 | B48: 9997.4 | C48: =B48/B49-1 -> -0.0095406045 | D48: -0.0095 | E48: 45311 | F48: 21571.8 | G48: =F48/F49-1 -> -0.0023401658 | H48: -0.0023 | L48: weight of equity(%) | M48: =M47*100 -> 25.078282 | N48: =N47*100 -> 17.314552 | O48: =O47*100 -> 29.185809 | P48: =P47*100 -> 52.10587
A49: 45310 | B49: 10093.7 | C49: =B49/B50-1 -> 0.020364427 | D49: 0.0204 | E49: 45310 | F49: 21622.4 | G49: =F49/F50-1 -> 0.007461939 | H49: 0.0075 | L49: WACC(%) | M49: #REF! | N49: #REF! | O49: #REF! | P49: #REF!
A50: 45309 | B50: 9892.25 | C50: =B50/B51-1 -> 0.0038154577 | D50: 0.0038 | E50: 45309 | F50: 21462.25 | G50: =F50/F51-1 -> -0.0050853075 | H50: -0.0051 | L50: WACC(%) | M50: 0.242 | N50: 0.1963 | O50: 0.2813 | P50: 0.5341
A51: 45308 | B51: 9854.65 | C51: =B51/B52-1 -> -0.011530051 | D51: -0.0115 | E51: 45308 | F51: 21571.95 | G51: =F51/F52-1 -> -0.020894323 | H51: -0.0209 | L51: Average WACC | M51: =(M50+N50+O50+P50)/4 -> 0.313425
A52: 45307 | B52: 9969.6 | C52: =B52/B53-1 -> 0.0015118715 | D52: 0.0015 | E52: 45307 | F52: 22032.3 | G52: =F52/F53-1 -> -0.002948304 | H52: -0.0029 | L52: Average WACC | M52: =(M50+N50+O50+P50)/4 -> 0.313425
A53: 45306 | B53: 9954.55 | C53: =B53/B54-1 -> 0.01489532 | D53: 0.0149 | E53: 45306 | F53: 22097.45 | G53: =F53/F54-1 -> 0.0092671464 | H53: 0.0093
...

Sheet AMBUJA
A1: Date | B1: Price | C1: change | D1: Change % | E1: Date | F1: Price | G1: change | H1: Change % | I1: beta | J1: beta(regression) | M1: =(F2/F744)^(1/3) -> 1.1451568
A2: 45379 | B2: 612.35 | C2: =B2/B3-1 -> 0.018038238 | D2: 0.018 | E2: 45379 | F2: 22326.9 | G2: =F2/F3-1 -> 0.0091870012 | H2: 0.0092 | I2: =_xlfn.COVARIANCE.P(C2:C743,G2:G743)/_xlfn.VAR.P(G2:G743) -> 1.056832 | J2: =_xlfn.COVARIANCE.P(D2:D743,H2:H743)/_xlfn.VAR.P(H2:H743) -> 1.0570445 | L2: Erm | M2: =M1-1 -> 0.14515679 | N2: Rf | O2: 0.065991
A3: 45378 | B3: 601.5 | C3: =B3/B4-1 -> 0.010839425 | D3: 0.0108 | E3: 45378 | F3: 22123.65 | G3: =F3/F4-1 -> 0.0054056633 | H3: 0.0054 | M3: 0.1452 | O3: =O2 -> 0.065991
A4: 45377 | B4: 595.05 | C4: =B4/B5-1 -> 0.0096716722 | D4: 0.0097 | E4: 45377 | F4: 22004.7 | G4: =F4/F5-1 -> -0.004165771 | H4: -0.0042
A5: 45373 | B5: 589.35 | C5: =B5/B6-1 -> 0.0036614441 | D5: 0.0037 | E5: 45373 | F5: 22096.75 | G5: =F5/F6-1 -> 0.0038524529 | H5: 0.0039 | L5: premium | M5: =M2-O3 -> 0.079165794
A6: 45372 | B6: 587.2 | C6: =B6/B7-1 -> 0.018825367 | D6: 0.0188 | E6: 45372 | F6: 22011.95 | G6: =F6/F7-1 -> 0.0079147034 | H6: 0.0079 | L6: beta premium | M6: =M5*I2 -> 0.083664946
A7: 45371 | B7: 576.35 | C7: =B7/B8-1 -> -0.0068068241 | D7: -0.0068 | E7: 45371 | F7: 21839.1 | G7: =F7/F8-1 -> 0.00099232495 | H7: 0.001 | L7: Ke(ERi) | M7: =M6+O3 -> 0.14965595 | N7: =M7*100 -> 14.965595
A8: 45370 | B8: 580.3 | C8: =B8/B9-1 -> -0.0074403489 | D8: -0.0074 | E8: 45370 | F8: 21817.45 | G8: =F8/F9-1 -> -0.010802196 | H8: -0.0108 | L8: (cost of equity) | N8: =M7 -> 0.14965595
A9: 45369 | B9: 584.65 | C9: =B9/B10-1 -> -0.026799834 | D9: -0.0268 | E9: 45369 | F9: 22055.7 | G9: =F9/F10-1 -> 0.0014688955 | H9: 0.0015
A10: 45366 | B10: 600.75 | C10: =B10/B11-1 -> 0.031419006 | D10: 0.0314 | E10: 45366 | F10: 22023.35 | G10: =F10/F11-1 -> -0.0055674334 | H10: -0.0056
A11: 45365 | B11: 582.45 | C11: =B11/B12-1 -> 0.041484131 | D11: 0.0415 | E11: 45365 | F11: 22146.65 | G11: =F11/F12-1 -> 0.0067711624 | H11: 0.0068
A12: 45364 | B12: 559.25 | C12: =B12/B13-1 -> -0.048166114 | D12: -0.0482 | E12: 45364 | F12: 21997.7 | G12: =F12/F13-1 -> -0.015132725 | H12: -0.0151
A13: 45363 | B13: 587.55 | C13: =B13/B14-1 -> -0.024084378 | D13: -0.0241 | E13: 45363 | F13: 22335.7 | G13: =F13/F14-1 -> 0.00013657134 | H13: 0.0001
A14: 45362 | B14: 602.05 | C14: =B14/B15-1 -> -0.0018237586 | D14: -0.0018 | E14: 45362 | F14: 22332.65 | G14: =F14/F15-1 -> -0.0071531617 | H14: -0.0072
A15: 45358 | B15: 603.15 | C15: =B15/B16-1 -> 0.0081063012 | D15: 0.0081 | E15: 45358 | F15: 22493.55 | G15: =F15/F16-1 -> 0.00086766738 | H15: 0.0009
A16: 45357 | B16: 598.3 | C16: =B16/B17-1 -> -0.024139618 | D16: -0.0241 | E16: 45357 | F16: 22474.05 | G16: =F16/F17-1 -> 0.0052669717 | H16: 0.0053
A17: 45356 | B17: 613.1 | C17: =B17/B18-1 -> -0.006562424 | D17: -0.0066 | E17: 45356 | F17: 22356.3 | G17: =F17/F18-1 -> -0.0022003428 | H17: -0.0022
A18: 45355 | B18: 617.15 | C18: =B18/B19-1 -> -0.0029081509 | D18: -0.0029 | E18: 45355 | F18: 22405.6 | G18: =F18/F19-1 -> 0.0012154578 | H18: 0.0012
A19: 45353 | B19: 618.95 | C19: =B19/B20-1 -> 0.0021858808 | D19: 0.0022 | E19: 45353 | F19: 22378.4 | G19: =F19/F20-1 -> 0.0017749426 | H19: 0.0018
A20: 45352 | B20: 617.6 | C20: =B20/B21-1 -> 0.019310117 | D20: 0.0193 | E20: 45352 | F20: 22338.75 | G20: =F20/F21-1 -> 0.016192205 | H20: 0.0162
... A34: 45334 | B34: 563.5 | C34: =B34/B35-1 -> -0.022040958 | D34: -0.022 | E34: 45334 | F34: 21616.05 | G34: =F34/F35-1 -> -0.0076414553 | H34: -0.0076
A35: 45331 | B35: 576.2 | C35: =B35/B36-1 -> 0.022809976 | D35: 0.0228 | E35: 45331 | F35: 21782.5 | G35: =F35/F36-1 -> 0.0029721958 | H35: 0.003 | L35: COST OF DEBT
A36: 45330 | B36: 563.35 | C36: =B36/B37-1 -> -0.0085357269 | D36: -0.0085 | E36: 45330 | F36: 21717.95 | G36: =F36/F37-1 -> -0.0096919815 | H36: -0.0097 | L36: Year | M36: 2021 | N36: 2022 | O36: 2023
A37: 45329 | B37: 568.2 | C37: =B37/B38-1 -> 0.0028238616 | D37: 0.0028 | E37: 45329 | F37: 21930.5 | G37: =F37/F38-1 -> 5.0160971e-05 | H37: 0.0001 | L37: Total Debt (Crores) | M37: 3937 | N37: 236.91 | O37: 1099.55
A38: 45328 | B38: 566.6 | C38: =B38/B39-1 -> 0.020900901 | D38: 0.0209 | E38: 45328 | F38: 21929.4 | G38: =F38/F39-1 -> 0.007243348 | H38: 0.0072 | L38: Interest Paid(crores) | M38: 90.94 | N38: 127.97 | O38: 162.25
A39: 45327 | B39: 555 | C39: =B39/B40-1 -> -0.0043057051 | D39: -0.0043 | E39: 45327 | F39: 21771.7 | G39: =F39/F40-1 -> -0.0037567837 | H39: -0.0038 | L39: Average Interest rate(%) | M39: =M38/M37 -> 0.023098806 | N39: =N38/N37 -> 0.54016293 | O39: =O38/O37 -> 0.14756037
A40: 45324 | B40: 557.4 | C40: =B40/B41-1 -> -0.013538625 | D40: -0.0135 | E40: 45324 | F40: 21853.8 | G40: =F40/F41-1 -> 0.0072059159 | H40: 0.0072 | L40: Taxable income(Crores) | M40: 2785.25 | N40: 3055.05 | O40: 3107.45
A41: 45323 | B41: 565.05 | C41: =B41/B42-1 -> 0.0084776013 | D41: 0.0085 | E41: 45323 | F41: 21697.45 | G41: =F41/F42-1 -> -0.0013003033 | H41: -0.0013 | L41: Tax Paid (Crores) | M41: 704.71 | N41: 501.56 | O41: 772.76 | R41: 0.086
A42: 45322 | B42: 560.3 | C42: =B42/B43-1 -> -0.018481212 | D42: -0.0185 | E42: 45322 | F42: 21725.7 | G42: =F42/F43-1 -> 0.0094600434 | H42: 0.0095 | L42: Tax rate | M42: =M41/M40 -> 0.25301499 | N42: =N41/N40 -> 0.16417407 | O42: =O41/O40 -> 0.24867979 | Q42: after tax cost of debt | R42: =R41*100 -> 8.6 | S42: %
A43: 45321 | B43: 570.85 | C43: =B43/B44-1 -> -0.0056610347 | D43: -0.0057 | E43: 45321 | F43: 21522.1 | G43: =F43/F44-1 -> -0.0099136979 | H43: -0.0099 | L43: After Tax cost of debt | M43: =M39*(1-M42) -> 0.017254462 | N43: =N39*(1-N42) -> 0.45148218 | O43: =O39*(1-O42) -> 0.11086509 | Q43: (average)
A44: 45320 | B44: 574.1 | C44: =B44/B45-1 -> 0.024904044 | D44: 0.0249 | E44: 45320 | F44: 21737.6 | G44: =F44/F45-1 -> 0.018030591 | H44: 0.018 | L44: Total Equity (crores) | M44: 22207 | N44: 289 | O44: 289
A45: 45316 | B45: 560.15 | C45: =B45/B46-1 -> 0.061996398 | D45: 0.062 | E45: 45316 | F45: 21352.6 | G45: =F45/F46-1 -> -0.0047240718 | H45: -0.0047 | L45: weight of debt | M45: =M37/(M37+M38) -> 0.9774227 | N45: =N37/(N37+N38) -> 0.64928196 | O45: =O37/(O37+O38) -> 0.87141385
A46: 45315 | B46: 527.45 | C46: =B46/B47-1 -> 0.0045709932 | D46: 0.0046 | E46: 45315 | F46: 21453.95 | G46: =F46/F47-1 -> 0.010130045 | H46: 0.0101 | L46: weight of debt(%) | M46: =M45*100 -> 97.74227 | N46: =N45*100 -> 64.928196 | O46: =O45*100 -> 87.141385
A47: 45314 | B47: 525.05 | C47: =B47/B48-1 -> -0.029033749 | D47: -0.029 | E47: 45314 | F47: 21238.8 | G47: =F47/F48-1 -> -0.01543682 | H47: -0.0154 | L47: weight of equity | M47: =1-M45 -> 0.022577298 | N47: =1-N45 -> 0.35071804 | O47: =1-O45 -> 0.12858615
A48: 45311 | B48: 540.75 | C48: =B48/B49-1 -> 0.006795755 | D48: 0.0068 | E48: 45311 | F48: 21571.8 | G48: =F48/F49-1 -> -0.0023401658 | H48: -0.0023 | L48: weight of equity(%) | M48: =M47*100 -> 2.2577298 | N48: =N47*100 -> 35.071804 | O48: =O47*100 -> 12.858615
A49: 45310 | B49: 537.1 | C49: =B49/B50-1 -> 0.024706668 | D49: 0.0247 | E49: 45310 | F49: 21622.4 | G49: =F49/F50-1 -> 0.007461939 | H49: 0.0075 | L49: WACC(%) | M49: #REF! | N49: #REF! | O49: #REF!
A50: 45309 | B50: 524.15 | C50: =B50/B51-1 -> 0.0069157622 | D50: 0.0069 | E50: 45309 | F50: 21462.25 | G50: =F50/F51-1 -> -0.0050853075 | H50: -0.0051 | L50: WACC(%) | M50: 0.0232 | N50: 0.392 | O50: 0.1328
A51: 45308 | B51: 520.55 | C51: =B51/B52-1 -> -0.015415169 | D51: -0.0154 | E51: 45308 | F51: 21571.95 | G51: =F51/F52-1 -> -0.020894323 | H51: -0.0209 | L51: Average WACC | M51: =(M50+N50+O50)/3 -> 0.18266667
A52: 45307 | B52: 528.7 | C52: =B52/B53-1 -> -0.0051745225 | D52: -0.0052 | E52: 45307 | F52: 22032.3 | G52: =F52/F53-1 -> -0.002948304 | H52: -0.0029 | L52: Average WACC | M52: 0.1827
A53: 45306 | B53: 531.45 | C53: =B53/B54-1 -> -0.0017843727 | D53: -0.0018 | E53: 45306 | F53: 22097.45 | G53: =F53/F54-1 -> 0.0092671464 | H53: 0.0093
...

Sheet ACC
A1: Date | B1: Price | C1: change | D1: Change % | E1: Date | F1: Price | G1: change | H1: Change % | I1: beta | J1: beta(regression) | M1: =(F2/F744)^(1/3) -> 1.1451568
A2: 45379 | B2: 2491.7 | C2: =B2/B3-1 -> 0.015321299 | D2: 0.0153 | E2: 45379 | F2: 22326.9 | G2: =F2/F3-1 -> 0.0091870012 | H2: 0.0092 | I2: =_xlfn.COVARIANCE.P(C2:C743,G2:G743)/_xlfn.VAR.P(G2:G743) -> 1.0107792 | J2: =_xlfn.COVARIANCE.P(D2:D743,H2:H743)/_xlfn.VAR.P(H2:H743) -> 1.010716 | L2: Erm | M2: =M1-1 -> 0.14515679 | N2: Rf | O2: 0.065991
A3: 45378 | B3: 2454.1 | C3: =B3/B4-1 -> 0.0016734694 | D3: 0.0017 | E3: 45378 | F3: 22123.65 | G3: =F3/F4-1 -> 0.0054056633 | H3: 0.0054 | M3: 0.1452 | O3: =O2 -> 0.065991
A4: 45377 | B4: 2450 | C4: =B4/B5-1 -> 0.0027627136 | D4: 0.0028 | E4: 45377 | F4: 22004.7 | G4: =F4/F5-1 -> -0.004165771 | H4: -0.0042
A5: 45373 | B5: 2443.25 | C5: =B5/B6-1 -> 0.001804129 | D5: 0.0018 | E5: 45373 | F5: 22096.75 | G5: =F5/F6-1 -> 0.0038524529 | H5: 0.0039 | L5: premium | M5: =M2-O3 -> 0.079165794
A6: 45372 | B6: 2438.85 | C6: =B6/B7-1 -> 0.017162281 | D6: 0.0172 | E6: 45372 | F6: 22011.95 | G6: =F6/F7-1 -> 0.0079147034 | H6: 0.0079 | L6: beta premium | M6: =M5*I2 -> 0.080019134
A7: 45371 | B7: 2397.7 | C7: =B7/B8-1 -> -0.0023716402 | D7: -0.0024 | E7: 45371 | F7: 21839.1 | G7: =F7/F8-1 -> 0.00099232495 | H7: 0.001 | L7: Ke(ERi) | M7: =M6+O3 -> 0.14601013 | N7: =M7*100 -> 14.601013
A8: 45370 | B8: 2403.4 | C8: =B8/B9-1 -> -0.01562532 | D8: -0.0156 | E8: 45370 | F8: 21817.45 | G8: =F8/F9-1 -> -0.010802196 | H8: -0.0108 | L8: (cost of equity) | N8: =M7 -> 0.14601013
A9: 45369 | B9: 2441.55 | C9: =B9/B10-1 -> -0.024531053 | D9: -0.0245 | E9: 45369 | F9: 22055.7 | G9: =F9/F10-1 -> 0.0014688955 | H9: 0.0015
A10: 45366 | B10: 2502.95 | C10: =B10/B11-1 -> 0.008400145 | D10: 0.0084 | E10: 45366 | F10: 22023.35 | G10: =F10/F11-1 -> -0.0055674334 | H10: -0.0056
A11: 45365 | B11: 2482.1 | C11: =B11/B12-1 -> 0.038926793 | D11: 0.0389 | E11: 45365 | F11: 22146.65 | G11: =F11/F12-1 -> 0.0067711624 | H11: 0.0068
A12: 45364 | B12: 2389.1 | C12: =B12/B13-1 -> -0.067340725 | D12: -0.0673 | E12: 45364 | F12: 21997.7 | G12: =F12/F13-1 -> -0.015132725 | H12: -0.0151
A13: 45363 | B13: 2561.6 | C13: =B13/B14-1 -> -0.030394792 | D13: -0.0304 | E13: 45363 | F13: 22335.7 | G13: =F13/F14-1 -> 0.00013657134 | H13: 0.0001
A14: 45362 | B14: 2641.9 | C14: =B14/B15-1 -> 0.0011747764 | D14: 0.0012 | E14: 45362 | F14: 22332.65 | G14: =F14/F15-1 -> -0.0071531617 | H14: -0.0072
A15: 45358 | B15: 2638.8 | C15: =B15/B16-1 -> -0.0012112036 | D15: -0.0012 | E15: 45358 | F15: 22493.55 | G15: =F15/F16-1 -> 0.00086766738 | H15: 0.0009
A16: 45357 | B16: 2642 | C16: =B16/B17-1 -> -0.010023419 | D16: -0.01 | E16: 45357 | F16: 22474.05 | G16: =F16/F17-1 -> 0.0052669717 | H16: 0.0053
A17: 45356 | B17: 2668.75 | C17: =B17/B18-1 -> -0.0099790403 | D17: -0.01 | E17: 45356 | F17: 22356.3 | G17: =F17/F18-1 -> -0.0022003428 | H17: -0.0022
A18: 45355 | B18: 2695.65 | C18: =B18/B19-1 -> -0.0025531443 | D18: -0.0026 | E18: 45355 | F18: 22405.6 | G18: =F18/F19-1 -> 0.0012154578 | H18: 0.0012
A19: 45353 | B19: 2702.55 | C19: =B19/B20-1 -> 0.0026340685 | D19: 0.0026 | E19: 45353 | F19: 22378.4 | G19: =F19/F20-1 -> 0.0017749426 | H19: 0.0018
A20: 45352 | B20: 2695.45 | C20: =B20/B21-1 -> 0.025158788 | D20: 0.0252 | E20: 45352 | F20: 22338.75 | G20: =F20/F21-1 -> 0.016192205 | H20: 0.0162
... A34: 45334 | B34: 2636.35 | C34: =B34/B35-1 -> 0.0031582352 | D34: 0.0032 | E34: 45334 | F34: 21616.05 | G34: =F34/F35-1 -> -0.0076414553 | H34: -0.0076
A35: 45331 | B35: 2628.05 | C35: =B35/B36-1 -> 0.04667742 | D35: 0.0467 | E35: 45331 | F35: 21782.5 | G35: =F35/F36-1 -> 0.0029721958 | H35: 0.003 | L35: COST OF DEBT
A36: 45330 | B36: 2510.85 | C36: =B36/B37-1 -> 0.002115304 | D36: 0.0021 | E36: 45330 | F36: 21717.95 | G36: =F36/F37-1 -> -0.0096919815 | H36: -0.0097 | L36: Year | M36: 2021 | N36: 2022 | O36: 2023 | P36: 2024
A37: 45329 | B37: 2505.55 | C37: =B37/B38-1 -> -0.0089785425 | D37: -0.009 | E37: 45329 | F37: 21930.5 | G37: =F37/F38-1 -> 5.0160971e-05 | H37: 0.0001 | L37: Total Debt (Crores) | M37: 1255.88 | N37: 1318.1 | O37: 1530.4 | P37: 3548.5
A38: 45328 | B38: 2528.25 | C38: =B38/B39-1 -> 0.016913362 | D38: 0.0169 | E38: 45328 | F38: 21929.4 | G38: =F38/F39-1 -> 0.007243348 | H38: 0.0072 | L38: Interest Paid(crores) | M38: 57.04 | N38: 54.63 | O38: 77.18 | P38: 153.79
A39: 45327 | B39: 2486.2 | C39: =B39/B40-1 -> -0.0053011663 | D39: -0.0053 | E39: 45327 | F39: 21771.7 | G39: =F39/F40-1 -> -0.0037567837 | H39: -0.0038 | L39: Average Interest rate(%) | M39: =M38/M37 -> 0.045418352 | N39: =N38/N37 -> 0.041446021 | O39: =O38/O37 -> 0.05043126 | P39: =P38/P37 -> 0.043339439
A40: 45324 | B40: 2499.45 | C40: =B40/B41-1 -> -0.012075099 | D40: -0.0121 | E40: 45324 | F40: 21853.8 | G40: =F40/F41-1 -> 0.0072059159 | H40: 0.0072 | L40: Taxable income(Crores) | M40: 25063.8 | N40: 871.25 | O40: 1182.13 | P40: 2519.08
A41: 45323 | B41: 2530 | C41: =B41/B42-1 -> -0.0056204064 | D41: -0.0056 | E41: 45323 | F41: 21697.45 | G41: =F41/F42-1 -> -0.0013003033 | H41: -0.0013 | L41: Tax Paid (Crores) | M41: 6432.8 | N41: 2217 | O41: 1814.4 | P41: 4227.7 | S41: 0.086
A42: 45322 | B42: 2544.3 | C42: =B42/B43-1 -> 0.012394803 | D42: 0.0124 | E42: 45322 | F42: 21725.7 | G42: =F42/F43-1 -> 0.0094600434 | H42: 0.0095 | L42: Tax rate | M42: =M41/M40 -> 0.25665701 | N42: =N41/N40 -> 2.5446198 | O42: =O41/O40 -> 1.5348566 | P42: =P41/P40 -> 1.6782714 | R42: after tax cost of debt | S42: =S41*100 -> 8.6 | T42: %
A43: 45321 | B43: 2513.15 | C43: =B43/B44-1 -> 0.0081230695 | D43: 0.0081 | E43: 45321 | F43: 21522.1 | G43: =F43/F44-1 -> -0.0099136979 | H43: -0.0099 | L43: After Tax cost of debt | M43: =M39*(1-M42) -> 0.033761414 | N43: =N39*(1-N42) -> -0.064018344 | O43: =O39*(1-O42) -> -0.026973491 | P43: =P39*(1-P42) -> -0.029395904 | R43: (average)
A44: 45320 | B44: 2492.9 | C44: =B44/B45-1 -> 0.010232407 | D44: 0.0102 | E44: 45320 | F44: 21737.6 | G44: =F44/F45-1 -> 0.018030591 | H44: 0.018 | L44: Total Equity (crores) | M44: 143121.8 | N44: 138895 | O44: 14149.5 | P44: 163333.1
A45: 45316 | B45: 2467.65 | C45: =B45/B46-1 -> 0.10133446 | D45: 0.1013 | E45: 45316 | F45: 21352.6 | G45: =F45/F46-1 -> -0.0047240718 | H45: -0.0047 | L45: weight of debt | M45: =M37/(M37+M44) -> 0.0086985745 | N45: =N37/(N37+N44) -> 0.0094006908 | O45: =O37/(O37+O44) -> 0.097602663 | P45: =P37/(P37+P44) -> 0.021263578
A46: 45315 | B46: 2240.6 | C46: =B46/B47-1 -> 0.014787473 | D46: 0.0148 | E46: 45315 | F46: 21453.95 | G46: =F46/F47-1 -> 0.010130045 | H46: 0.0101 | L46: weight of debt(%) | M46: =M45*100 -> 0.86985745 | N46: =N45*100 -> 0.94006908 | O46: =O45*100 -> 9.7602663 | P46: =P45*100 -> 2.1263578
A47: 45314 | B47: 2207.95 | C47: =B47/B48-1 -> -0.035871796 | D47: -0.0359 | E47: 45314 | F47: 21238.8 | G47: =F47/F48-1 -> -0.01543682 | H47: -0.0154 | L47: weight of equity | M47: =1-M45 -> 0.99130143 | N47: =1-N45 -> 0.99059931 | O47: =1-O45 -> 0.90239734 | P47: =1-P45 -> 0.97873642
A48: 45311 | B48: 2290.1 | C48: =B48/B49-1 -> 0.0057090159 | D48: 0.0057 | E48: 45311 | F48: 21571.8 | G48: =F48/F49-1 -> -0.0023401658 | H48: -0.0023 | L48: weight of equity(%) | M48: =M47*100 -> 99.130143 | N48: =N47*100 -> 99.059931 | O48: =O47*100 -> 90.239734 | P48: =P47*100 -> 97.873642
A49: 45310 | B49: 2277.1 | C49: =B49/B50-1 -> 0.0075217911 | D49: 0.0075 | E49: 45310 | F49: 21622.4 | G49: =F49/F50-1 -> 0.007461939 | H49: 0.0075 | L49: WACC(%) | M49: #REF! | N49: #REF! | O49: #REF! | P49: =(P46*P43)+(P48*O4) -> -0.06250621
A50: 45309 | B50: 2260.1 | C50: =B50/B51-1 -> 0.0036859401 | D50: 0.0037 | E50: 45309 | F50: 21462.25 | G50: =F50/F51-1 -> -0.0050853075 | H50: -0.0051 | L50: WACC(%) | M50: 0.2796 | N50: 0.2785 | O50: 0.2517 | P50: -0.0625
A51: 45308 | B51: 2251.8 | C51: =B51/B52-1 -> -0.018588333 | D51: -0.0186 | E51: 45308 | F51: 21571.95 | G51: =F51/F52-1 -> -0.020894323 | H51: -0.0209 | L51: Average WACC | M51: =(M50+N50+O50+P50)/4 -> 0.186825
A52: 45307 | B52: 2294.45 | C52: =B52/B53-1 -> -0.011183417 | D52: -0.0112 | E52: 45307 | F52: 22032.3 | G52: =F52/F53-1 -> -0.002948304 | H52: -0.0029 | L52: Average WACC | M52: =ACC!$M$51 -> 0.186825
A53: 45306 | B53: 2320.4 | C53: =B53/B54-1 -> -0.0051449151 | D53: -0.0051 | E53: 45306 | F53: 22097.45 | G53: =F53/F54-1 -> 0.0092671464 | H53: 0.0093
...

Sheet PART 2
B2: Financial Data Summary (in ₹ Crores) | N2: Year | O2: Interest Coverage Ratio | Q2: Year | R2: Cash Flow Coverage Ratio
N3: 2022 | O3: 1.26 | Q3: 2022 | R3: 0.06
B4: Total Debt | C4: 4675 | D4: 4850 | E4: 4800 | N4: 2023 | O4: 0.93 | Q4: 2023 | R4: 0.04 | Y4: Year | Z4: Current Assets(₹ Cr) | AA4: Short-Term Liabilities (₹ Cr) | AB4: Long-Term Liabilities (₹ Cr) | AC4: Debt-to-Equity Ratio | AD4: Leverage Ratio (Current Liabilities/Current Assets) | AE4: Cash Reserves (₹ Cr) | AF4: Dividend Policy | AH4: Year | AI4: Cash Reserves (₹ Cr) | AJ4: Cash Flow from Operations (₹ Cr) | AK4: Interest Expense (₹ Cr) | AL4: Dividend (₹/Share)
B5: Shareholder's equity | C5: 3050 | D5: 3010 | E5: 2900 | N5: 2024 | O5: -1.39 | Q5: 2024 | R5: -0.04 | Y5: 2022 | Z5: 23986 | AA5: 22307 | AB5: 12165 | AC5: 0.79 | AD5: 0.93 | AE5: 688.4 | AF5: None | AH5: 2022 | AI5: 688.4 | AJ5: 270 | AK5: 210 | AL5: None | AS5: METRIC | AT5: FY 2022 | AU5: FY 2023 | AV5: FY 2024 | AY5: Metric | AZ5: FY 2022 | BA5: FY 2023 | BB5: FY 2024 | BC5: Interpretation | BG5: Metric | BH5: FY 2022 | BI5: FY 2023 | BJ5: FY 2024
B6: EBIT [Operating Income] | C6: 265 | D6: 185 | E6: -328 | Y6: 2023 | Z6: 32147 | AA6: 27968 | AB6: 14153 | AC6: 0.87 | AD6: 1 | AE6: 852.5 | AF6: None | AH6: 2023 | AI6: 852.5 | AJ6: 200 | AK6: 199 | AL6: None | AS6: Total Debt | AT6: 4675 | AU6: 4850 | AV6: 4800 | AY6: Interest Coverage Ratio | AZ6: 1.26 | BA6: 0.93 | BB6: -1.39 | BC6: Declining ability to cover interest payments | BF6: Focus on Debt Reduction | BG6: Total Debt (₹ crore) | BH6: 4675 | BI6: 4850 | BJ6: 4800
B7: Interest Expense | C7: 210 | D7: 199 | E7: 236 | Y7: 2024 | Z7: 34912 | AA7: 23042 | AB7: 12165 | AC7: 0.66 | AD7: 0.96 | AE7: 748.9 | AF7: None | AH7: 2024 | AI7: 748.9 | AJ7: -195 | AK7: 236 | AL7: None | AS7: Shareholder's equity | AT7: 3050 | AU7: 3010 | AV7: 2900 | AY7: Debt-to-Equity Ratio | AZ7: 1.53 | BA7: 1.61 | BB7: 1.66 | BC7: Increasing financial leverage | BG7: Interest Expense (₹ crore) | BH7: 210 | BI7: 199 | BJ7: 236
B8: Cashflow from Operations | C8: 270 | D8: 200 | E8: -195 | AS8: EBIT [Operating Income] | AT8: 265 | AU8: 185 | AV8: -328 | AY8: EBIT (₹ crore) | AZ8: 265 | BA8: 185 | BB8: -328 | BC8: Negative EBIT in FY 2024 limits dividend capacity | BG8: Debt-to-Equity Ratio | BH8: 1.53 | BI8: 1.61 | BJ8: 1.66
AS9: Interest Expense | AT9: 210 | AU9: 199 | AV9: 236 | AY9: Interest Expense (₹ crore) | AZ9: 210 | BA9: 199 | BB9: 236 | BC9: High fixed interest burden | BF9: Retention of Earnings | BG9: EBIT (₹ crore) | BH9: 265 | BI9: 185 | BJ9: -328
BG10: Shareholder Equity (₹ crore) | BH10: 3050 | BI10: 3010 | BJ10: 2900
M11: CRITERIA: | Q11: CRITERIA: | BF11: Stock Buybacks | BG11: Hypothetical Buyback (₹ crore) | BH11: 500 | BI11: - | BJ11: -
AE12: Leverage Ratios | BG12: Shares Bought Back (crore) | BH12: 2.5 | BI12: - | BJ12: -
BF13: Commitment to Dividends | BG13: Dividend Payout Foregone (₹ crore) | BH13: 200 | BI13: 200 | BJ13: 200
BG14: Debt Reduction Over 3 Years (₹ crore) | BH14: 600 | BI14: - | BJ14: -
BG15: Interest Savings (₹ crore) | BH15: 30 | BI15: - | BJ15: -
B16: Year | C16: Debt-to-Equity Ratio | BF16: Market Value Enhancement | BG16: Shareholder Equity (₹ crore) | BH16: 3050 | BI16: 3010 | BJ16: 2900
B17: 2022 | C17: 1.53 | BG17: Dividend Yield Foregone (%) | BH17: 2 | BI17: 2 | BJ17: 2
B18: 2023 | C18: 1.61
B19: 2024 | C19: 1.66
B26: Year | C26: Debt Proportion % | D26: Equity Proportion %
B27: FY 2022 | C27: 0.3263 | D27: 0.3404
B28: FY 2023 | C28: 0.3386 | D28: 0.3359
B29: FY 2024 | C29: 0.335 | D29: 0.3236
AI32: Analysis of Financing Needs
AD33: Cash Reserves | AI33: 1. Short-Term Liabilities vs. Current Assets (Leverage Ratio)
AI34: FY 2022 (0.93): Liquidity was manageable, with current assets covering short-term liabilities adequately.
N35: INTERPRETATION | AI35: FY 2023 (1.00): Liquidity hit its limit, as short-term liabilities equaled current assets, reflecting higher dependency on short-term financing.
M36: FY 2022 | N36: The company barely covers interest payments from operational earnings; weak cash flow to support debt. | AI36: FY 2024 (0.96): Slight improvement due to better working capital management, but cash reserves indicate ongoing challenges.
M37: FY 2023 | N37: Decline in EBIT leads to reduced capacity to meet interest; reliance on external funds increases. | AI37: 2. Long-Term Liabilities and Debt-to-Equity Ratio
M38: FY 2024 | N38: Negative EBIT and cash flow indicate inability to service debt, signaling high financial distress. | AI38: Long-term liabilities increased in FY 2023 (₹14,153 Cr) but stabilized in FY 2024 (₹12,165 Cr), suggesting cautious debt management.
AI39: Debt-to-equity ratio dropped from 0.87 (FY 2023) to 0.66 (FY 2024), showing improved financial stability, though equity erosion continues due to operational losses.
M40: INSIGHTS | AI40: 3. Cash Reserves and Cash Flow from Operations
M41: "India Cements Ltd. showed a declining trend in its ability to service debt, with operational challenges intensifying in 2024." | AI41: Cash reserves increased in FY 2023 (₹852.5 Cr) but dropped to ₹748.9 Cr in FY 2024, signaling reduced liquidity amidst negative cash flow (-₹195 Cr).
M42: "Urgent actions like cost reduction, revenue growth, or restructuring are critical to address financial distress." | AI42: Negative operating cash flow in FY 2024 reflects an inability to generate enough internal funds to meet financing needs.
AI43: 4. Interest Expense and Dividend | AY43: 1. High Debt Levels and Interest Obligations
AI44: Interest expense increased from ₹199 Cr in FY 2023 to ₹236 Cr in FY 2024, adding pressure on debt servicing. | AY44: Debt Dependency: Total debt remains consistently high, at ₹4,675 crore in FY 2022, ₹4,850 crore in FY 2023, and ₹4,800 crore in FY 2024.
AI45: Dividend payouts remained suspended over all three years, prioritizing cash conservation. | AY45: Interest Expense: The interest expense is significant, standing at ₹210 crore in FY 2022, ₹199 crore in FY 2023, and ₹236 crore in FY 2024, consuming a major portion of cash flows.
AY46: EBIT-Interest Coverage:
N47: Recommendations for Debt Servicing | AY47: FY 2022: EBIT of ₹265 crore barely covers interest expense (1.26x).
N48: Reduce Debt: Explore refinancing or asset sales to lower interest obligations. | AA48: Capital Structure Analysis | AI48: Key Insights on Financing Needs | AY48: FY 2023: EBIT of ₹185 crore fails to fully cover interest expense (0.93x).
N49: Increase EBIT: Focus on operational efficiency and revenue growth to return to positive ICR. | AY49: FY 2024: EBIT is negative (-₹328 crore), meaning the company cannot cover its interest obligations.
...

Sheet PART 3
A1: India Cements | M1: Is the company capable of handling its financial obligations without facing difficulties?
B2: Rev | C2: Rev Growth | D2: NI | E2: NI Growth | G2: EPS(in Rs.) | H2: Current Assets | I2: Current Liabilities | J2: Current Ratio | L2: QUESTION NO.
A3: 2020 | B3: 5058 | D3: -36 | L3: 1)
A4: 2021 | B4: 4437 | C4: =(B4-B3)/B3 -> -0.1227758 | D4: 222 | E4: =(D4-D3)/ABS(D3) -> 7.1666667 | G4: 7.16 | H4: 1650 | I4: 2537 | J4: =H4/I4 -> 0.65037446
A5: 2022 | B5: 4713 | C5: =(B5-B4)/B4 -> 0.062204192 | D5: 39 | E5: =(D5-D4)/ABS(D4) -> -0.82432432 | G5: 1.26 | H5: 2381 | I5: 2689 | J5: =H5/I5 -> 0.88545928 | M5: Following ratios here depict:
A6: 2023 | B6: 5381 | C6: =(B6-B5)/B5 -> 0.14173562 | D6: -189 | E6: =(D6-D5)/ABS(D5) -> -5.8461538 | G6: -6.08 | H6: 3198 | I6: 2775 | J6: =H6/I6 -> 1.1524324 | M6: 1. Current Ratio - Current Ratio here measures whether company can meet it's short term obligations using its short term assets.
B7: Avg Rev Growth | C7: =AVERAGE(C4:C6) -> 0.027054672 | D7: Average NI Growth | E7: =AVERAGE(E4:E6) -> 0.16539617 | F7: Average EPS | G7: =AVERAGE(G4:G6) -> 0.78 | I7: Average CR | J7: =AVERAGE(J4:J6) -> 0.89608872 | M7: 2. D/E Ratio -D/E Ratio here measures the proportion of Debt financing relative to Equity financing
B8: Avg Rev Growth of industry | C8: =AVERAGE($C$7,$C$18,$C$29,$C$40) -> 0.12894596 | D8: Average NI Growth of Industry | E8: =AVERAGE($E$7,$E$18,$E$29,$E$40) -> 0.1669909 | F8: Industry Average EPS | G8: =AVERAGE($G$7,$G$18,$G$29,$G$40) -> 79.259167 | I8: Industry Average CR | J8: =AVERAGE($J$7,$J$18,$J$29,$J$40) -> 1.3119324 | M8: 3. Interest Coverage Ratio - Interest Coverage Ratio here depicts the ability to cover interest payments with operating income.
M11: Last 3 years average | N11: Current Ratio | O11: D/E Ratio | P11: Interest Coverage Ratio
A12: Ultra Tech | M12: India Cements | N12: 0.8961 | O12: 9.06 | P12: 0.93
B13: Rev | C13: Rev Growth | D13: NI | E13: NI Growth | G13: EPS(in Rs.) | H13: Current Assets | I13: Current Liabilities | J13: Current Ratio | M13: Industry Average | N13: 1.265 | O13: 9.21 | P13: 15.44
A14: 2020 | B14: 42430 | D14: 5751
A15: 2021 | B15: 44726 | C15: =(B15-B14)/B14 -> 0.054112656 | D15: 5462 | E15: =(D15-D14)/ABS(D14) -> -0.05025213 | G15: 199.4 | H15: 22992 | I15: 19587.76 | J15: =H15/I15 -> 1.1737942
A16: 2022 | B16: 52599 | C16: =(B16-B15)/B15 -> 0.17602737 | D16: 7334 | E16: =(D16-D15)/ABS(D15) -> 0.3427316 | G16: 189.26 | H16: 18991 | I16: 19172 | J16: =H16/I16 -> 0.99055915 | N16: INDIA CEMENTS | O16: INDUSTRY AVG
A17: 2023 | B17: 63240 | C17: =(B17-B16)/B16 -> 0.20230423 | D17: 5073 | E17: =(D17-D16)/ABS(D16) -> -0.30829016 | G17: 254.42 | H17: 21864 | I17: 22248 | J17: =H17/I17 -> 0.98274002 | M17: 2021 | N17: 0.6504 | O17: 1.2069
B18: Avg Rev Growth | C18: =AVERAGE(C15:C17) -> 0.14414808 | D18: Average NI Growth | E18: =AVERAGE(E15:E17) -> -0.0052702285 | F18: Average EPS | G18: =AVERAGE(G15:G17) -> 214.36 | I18: Average CR | J18: =AVERAGE(J15:J17) -> 1.0490311 | M18: 2022 | N18: 0.8855 | O18: 1.3966
B19: Avg Rev Growth of industry | C19: =AVERAGE($C$7,$C$18,$C$29,$C$40) -> 0.12894596 | D19: Average NI Growth of Industry | E19: =AVERAGE($E$7,$E$18,$E$29,$E$40) -> 0.1669909 | F19: Industry Average EPS | G19: =AVERAGE($G$7,$G$18,$G$29,$G$40) -> 79.259167 | I19: Industry Average CR | J19: =AVERAGE($J$7,$J$18,$J$29,$J$40) -> 1.3119324 | M19: 2023 | N19: 1.1524 | O19: 1.3323
A23: Ambuja
B24: Rev | C24: Rev Growth | D24: NI | E24: NI Growth | G24: EPS(in Rs.) | H24: Current Assets | I24: Current Liabilities | J24: Current Ratio
A25: 2020 | B25: 11743.86 | D25: 1790.1
A26: 2021 | B26: 14250.59 | C26: =(B26-B25)/B25 -> 0.21345026 | D26: 2080.54 | E26: =(D26-D25)/D25 -> 0.16224792 | G26: 10.33 | H26: 6774 | I26: 5357 | J26: =H26/I26 -> 1.2645137
A27: 2022 | B27: 20937.7 | C27: =(B27-B26)/B26 -> 0.46925145 | D27: 2553.49 | E27: =(D27-D26)/D26 -> 0.22732079 | G27: 12.86 | H27: 10876 | I27: 5436 | J27: =H27/I27 -> 2.0007358
A28: 2023 | B28: 18771.97 | C28: =(B28-B27)/B27 -> -0.10343686 | D28: 2334.69 | E28: =(D28-D27)/D27 -> -0.085686648 | G28: 11.74 | H28: 11246 | I28: 6423 | J28: =H28/I28 -> 1.7508952
B29: Avg Rev Growth | C29: =AVERAGE(C26:C28) -> 0.19308828 | D29: Average NI Growth | E29: =AVERAGE(E26:E28) -> 0.10129402 | F29: Average EPS | G29: =AVERAGE(G26:G28) -> 11.643333 | I29: Average CR | J29: =AVERAGE(J26:J28) -> 1.6720483
B30: Avg Rev Growth of industry | C30: =AVERAGE($C$7,$C$18,$C$29,$C$40) -> 0.12894596 | D30: Average NI Growth of Industry | E30: =AVERAGE($E$7,$E$18,$E$29,$E$40) -> 0.1669909 | F30: Industry Average EPS | G30: =AVERAGE($G$7,$G$18,$G$29,$G$40) -> 79.259167 | I30: Industry Average CR | J30: =AVERAGE($J$7,$J$18,$J$29,$J$40) -> 1.3119324
A34: ACC
B35: Rev | C35: Rev Growth | D35: NI | E35: NI Growth | G35: EPS(in Rs.) | H35: Current Assets | I35: Current Liabilities | J35: Current Ratio
A36: 2020 | B36: 13988.52 | D36: 1400.4
A37: 2021 | B37: 16356.11 | C37: =(B37-B36)/B36 -> 0.16925236 | D37: 1820.27 | E37: =(D37-D36)/D36 -> 0.29982148 | G37: 99.21 | H37: 8330 | I37: 4790 | J37: =H37/I37 -> 1.7390397
A38: 2022 | B38: 22547.15 | C38: =(B38-B37)/B37 -> 0.37851543 | D38: 869.91 | E38: =(D38-D37)/D37 -> -0.52209837 | G38: 47.13 | H38: 10246 | I38: 5993 | J38: =H38/I38 -> 1.7096613
A39: 2023 | B39: 20443.74 | C39: =(B39-B38)/B38 -> -0.093289396 | D39: 2124.24 | E39: =(D39-D38)/D38 -> 1.4419078 | G39: 124.42 | H39: 8124 | I39: 5630 | J39: =H39/I39 -> 1.442984
B40: Avg Rev Growth | C40: =AVERAGE(C37:C39) -> 0.1514928 | D40: Average NI Growth | E40: =AVERAGE(E37:E39) -> 0.40654363 | F40: Average EPS | G40: =AVERAGE(G37:G39) -> 90.253333 | I40: Average CR | J40: =AVERAGE(J37:J39) -> 1.6305617
B41: Avg Rev Growth of industry | C41: =AVERAGE($C$7,$C$18,$C$29,$C$40) -> 0.12894596 | D41: Average NI Growth of Industry | E41: =AVERAGE($E$7,$E$18,$E$29,$E$40) -> 0.1669909 | F41: Industry Average EPS | G41: =AVERAGE($G$7,$G$18,$G$29,$G$40) -> 79.259167 | I41: Industry Average CR | J41: =AVERAGE($J$7,$J$18,$J$29,$J$40) -> 1.3119324
A44: Last 3 Year Average | B44: Standard Deviation
A45: India Cements | B45: 0.424299
A46: Ultra Tech | B46: 0.227696
A47: Ambuja | B47: 0.344584
A48: ACC | B48: 0.290393
A49: Industry Average | B49: =AVERAGE(B45:B48) -> 0.321743
L50: Ranking- | M50: 2
...
